<robot name="metabot">

  <!-- Component body#1 -->

  <link name="trunk">
    <visual>
      <geometry>
        <mesh filename="package://urdf/1eb9a5a5dedcfc5b4983c431992cb663aa33356f.stl"/>
      </geometry>
      <material name="body_body_1_0_material">
        <color rgba="0.8 0.8 0.8 1.0"/>
      </material>
      <origin xyz="0 0 0" rpy="0 -0 0"/>
    </visual>
    <visual>
      <geometry>
        <mesh filename="package://urdf/510cc774b0998998f261ff5060f6c504b8aee728.stl"/>
      </geometry>
      <material name="body_fit_1_1_material">
        <color rgba="0.15 0.15 0.15 1.0"/>
      </material>
      <origin xyz="-0.025 0 0.044" rpy="0 -0 1.5708"/>
    </visual>
    <visual>
      <geometry>
        <mesh filename="package://urdf/1fb1200d4eecf508ae39178f782dc19c9f95171f.stl"/>
      </geometry>
      <material name="body_lipo_1_2_material">
        <color rgba="0.2 0.2 1 1.0"/>
      </material>
      <origin xyz="0.02 0 0.044" rpy="0 -0 1.5708"/>
    </visual>
    <visual>
      <geometry>
        <mesh filename="package://urdf/ec48c503b08df80db4b69bdca79c3c4abd9a9f79.stl"/>
      </geometry>
      <material name="body_mx64_1_3_material">
        <color rgba="0.15 0.2 0.15 1.0"/>
      </material>
      <origin xyz="0 -0.046375 0.0205" rpy="-1.22465e-16 3.14159 -1.22465e-16"/>
    </visual>
    <visual>
      <geometry>
        <mesh filename="package://urdf/25b260d037c322d47acdc54ca73d53b468bfe2d1.stl"/>
      </geometry>
      <material name="body_mx64_arm_1_4_material">
        <color rgba="0.5 0.5 0.5 1.0"/>
      </material>
      <origin xyz="3.07451e-34 -0.046375 0" rpy="-1.22465e-16 3.14159 -1.22465e-16"/>
    </visual>
    <visual>
      <geometry>
        <mesh filename="package://urdf/25b260d037c322d47acdc54ca73d53b468bfe2d1.stl"/>
      </geometry>
      <material name="body_mx64_arm_1_5_material">
        <color rgba="0.5 0.5 0.5 1.0"/>
      </material>
      <origin xyz="-3.52444e-34 -0.046375 0.044" rpy="-1.22465e-16 3.14159 -1.22465e-16"/>
    </visual>
    <visual>
      <geometry>
        <mesh filename="package://urdf/f14dd39e029f8996e3026773ee23983bf9c6aaf9.stl"/>
      </geometry>
      <material name="body_tag_1_6_material">
        <color rgba="0.9 0.9 0.9 1.0"/>
      </material>
      <origin xyz="0.035 -0.046375 0" rpy="3.14159 -1.22465e-16 1.5708"/>
    </visual>
    <visual>
      <geometry>
        <mesh filename="package://urdf/e9f087865029fcd254bd6913f6f702b6f701e249.stl"/>
      </geometry>
      <material name="body_mx28_1_7_material">
        <color rgba="0.15 0.2 0.15 1.0"/>
      </material>
      <origin xyz="0 -0.046375 0.159" rpy="1.5708 -1.5708 0"/>
    </visual>
    <visual>
      <geometry>
        <mesh filename="package://urdf/f3516f363c4dfdeb49895426ad64acab9d85cee8.stl"/>
      </geometry>
      <material name="body_mx28_arm_1_8_material">
        <color rgba="0.5 0.5 0.5 1.0"/>
      </material>
      <origin xyz="-3.9413e-18 -0.064125 0.159" rpy="1.5708 -1.5708 0"/>
    </visual>
    <visual>
      <geometry>
        <mesh filename="package://urdf/f3516f363c4dfdeb49895426ad64acab9d85cee8.stl"/>
      </geometry>
      <material name="body_mx28_arm_1_9_material">
        <color rgba="0.5 0.5 0.5 1.0"/>
      </material>
      <origin xyz="4.60743e-18 -0.025625 0.159" rpy="1.5708 -1.5708 0"/>
    </visual>
    <visual>
      <geometry>
        <mesh filename="package://urdf/f14dd39e029f8996e3026773ee23983bf9c6aaf9.stl"/>
      </geometry>
      <material name="body_tag_1_10_material">
        <color rgba="0.9 0.9 0.9 1.0"/>
      </material>
      <origin xyz="-3.9413e-18 -0.064125 0.134" rpy="-1.5708 -2.22045e-16 3.14159"/>
    </visual>
    <visual>
      <geometry>
        <mesh filename="package://urdf/ec48c503b08df80db4b69bdca79c3c4abd9a9f79.stl"/>
      </geometry>
      <material name="body_mx64_1_11_material">
        <color rgba="0.15 0.2 0.15 1.0"/>
      </material>
      <origin xyz="0 0.046375 0.0205" rpy="-1.22465e-16 3.14159 -1.22465e-16"/>
    </visual>
    <visual>
      <geometry>
        <mesh filename="package://urdf/25b260d037c322d47acdc54ca73d53b468bfe2d1.stl"/>
      </geometry>
      <material name="body_mx64_arm_1_12_material">
        <color rgba="0.5 0.5 0.5 1.0"/>
      </material>
      <origin xyz="3.07451e-34 0.046375 0" rpy="-1.22465e-16 3.14159 -1.22465e-16"/>
    </visual>
    <visual>
      <geometry>
        <mesh filename="package://urdf/25b260d037c322d47acdc54ca73d53b468bfe2d1.stl"/>
      </geometry>
      <material name="body_mx64_arm_1_13_material">
        <color rgba="0.5 0.5 0.5 1.0"/>
      </material>
      <origin xyz="-3.52444e-34 0.046375 0.044" rpy="-1.22465e-16 3.14159 -1.22465e-16"/>
    </visual>
    <visual>
      <geometry>
        <mesh filename="package://urdf/f14dd39e029f8996e3026773ee23983bf9c6aaf9.stl"/>
      </geometry>
      <material name="body_tag_1_14_material">
        <color rgba="0.9 0.9 0.9 1.0"/>
      </material>
      <origin xyz="0.035 0.046375 0" rpy="3.14159 -1.22465e-16 1.5708"/>
    </visual>
    <visual>
      <geometry>
        <mesh filename="package://urdf/e9f087865029fcd254bd6913f6f702b6f701e249.stl"/>
      </geometry>
      <material name="body_mx28_1_15_material">
        <color rgba="0.15 0.2 0.15 1.0"/>
      </material>
      <origin xyz="0 0.046375 0.159" rpy="-1.5708 -1.5708 0"/>
    </visual>
    <visual>
      <geometry>
        <mesh filename="package://urdf/f3516f363c4dfdeb49895426ad64acab9d85cee8.stl"/>
      </geometry>
      <material name="body_mx28_arm_1_16_material">
        <color rgba="0.5 0.5 0.5 1.0"/>
      </material>
      <origin xyz="6.11505e-18 0.064125 0.159" rpy="-1.5708 -1.5708 0"/>
    </visual>
    <visual>
      <geometry>
        <mesh filename="package://urdf/f3516f363c4dfdeb49895426ad64acab9d85cee8.stl"/>
      </geometry>
      <material name="body_mx28_arm_1_17_material">
        <color rgba="0.5 0.5 0.5 1.0"/>
      </material>
      <origin xyz="-7.14858e-18 0.025625 0.159" rpy="-1.5708 -1.5708 0"/>
    </visual>
    <visual>
      <geometry>
        <mesh filename="package://urdf/f14dd39e029f8996e3026773ee23983bf9c6aaf9.stl"/>
      </geometry>
      <material name="body_tag_1_18_material">
        <color rgba="0.9 0.9 0.9 1.0"/>
      </material>
      <origin xyz="6.11505e-18 0.064125 0.134" rpy="-1.5708 -2.22045e-16 -3.4451e-16"/>
    </visual>
    <visual>
      <geometry>
        <mesh filename="package://urdf/e9f087865029fcd254bd6913f6f702b6f701e249.stl"/>
      </geometry>
      <material name="body_mx28_1_19_material">
        <color rgba="0.15 0.2 0.15 1.0"/>
      </material>
      <origin xyz="0.025873 0 0.16193" rpy="0 -0 0"/>
    </visual>
    <visual>
      <geometry>
        <mesh filename="package://urdf/f3516f363c4dfdeb49895426ad64acab9d85cee8.stl"/>
      </geometry>
      <material name="body_mx28_arm_1_20_material">
        <color rgba="0.5 0.5 0.5 1.0"/>
      </material>
      <origin xyz="0.025873 0 0.17968" rpy="0 -0 0"/>
    </visual>
    <visual>
      <geometry>
        <mesh filename="package://urdf/f3516f363c4dfdeb49895426ad64acab9d85cee8.stl"/>
      </geometry>
      <material name="body_mx28_arm_1_21_material">
        <color rgba="0.5 0.5 0.5 1.0"/>
      </material>
      <origin xyz="0.025873 0 0.14118" rpy="0 -0 0"/>
    </visual>
    <visual>
      <geometry>
        <mesh filename="package://urdf/f14dd39e029f8996e3026773ee23983bf9c6aaf9.stl"/>
      </geometry>
      <material name="body_tag_1_22_material">
        <color rgba="0.9 0.9 0.9 1.0"/>
      </material>
      <origin xyz="0.000872999 0 0.17968" rpy="0 -0 1.5708"/>
    </visual>
    <visual>
      <geometry>
        <mesh filename="package://urdf/739804ae964e7755d0eecbc6e23b0a02954531ff.stl"/>
      </geometry>
      <material name="body_body_block_1_23_material">
        <color rgba="0.8 0.8 0.8 1.0"/>
      </material>
      <origin xyz="0 0 0" rpy="0 -0 3.14159"/>
    </visual>
    <inertial>
      <origin xyz="-0.0020209 -7.24982e-05 0.0765677" rpy="0 0 0"/>
      <mass value="1.59255"/>
      <inertia ixx="0.00665265"  ixy="-4.09628e-06"  ixz="1.79248e-06" iyy="0.00485314" iyz="2.41676e-06" izz="0.00387166" />
    </inertial>
    <collision>
      <origin xyz="-0.03505 0 0.0015" rpy="0 -0 3.14159"/>
      <geometry>
        <box size="0.0448 0.13355 0.0028"/>
      </geometry>
    </collision>
    <collision>
      <origin xyz="-0.01 0 0.0425" rpy="0 -0 3.14159"/>
      <geometry>
        <box size="0.0998 0.13355 0.0028"/>
      </geometry>
    </collision>
    <collision>
      <origin xyz="0.0075 0 0.1227" rpy="0 -0 3.14159"/>
      <geometry>
        <box size="0.0648 0.13355 0.0028"/>
      </geometry>
    </collision>
    <collision>
      <origin xyz="0.033 0.058375 0.0811" rpy="0 -0 3.14159"/>
      <geometry>
        <cylinder radius="0.0078" length="0.08"/>
      </geometry>
    </collision>
    <collision>
      <origin xyz="0.033 -0.058375 0.0811" rpy="0 -0 3.14159"/>
      <geometry>
        <cylinder radius="0.0078" length="0.08"/>
      </geometry>
    </collision>
    <collision>
      <origin xyz="-0.017 0.058375 0.0811" rpy="0 -0 3.14159"/>
      <geometry>
        <cylinder radius="0.0078" length="0.08"/>
      </geometry>
    </collision>
    <collision>
      <origin xyz="-0.017 -0.058375 0.0811" rpy="0 -0 3.14159"/>
      <geometry>
        <cylinder radius="0.0078" length="0.08"/>
      </geometry>
    </collision>
    <collision>
      <origin xyz="-0.0375 0 0.0975" rpy="0 -0 1.5708"/>
      <geometry>
        <box size="0.0828 0.0248 0.1068"/>
      </geometry>
    </collision>
    <collision>
      <origin xyz="0.0075 0 0.063" rpy="0 -0 1.5708"/>
      <geometry>
        <box size="0.1198 0.0248 0.0378"/>
      </geometry>
    </collision>
    <collision>
      <origin xyz="0.018 -0.046375 0.0205" rpy="3.14159 -1.22465e-16 1.5708"/>
      <geometry>
        <box size="0.04 0.0609 0.0408"/>
      </geometry>
    </collision>
    <collision>
      <origin xyz="-2.77556e-18 -0.046375 0.1465" rpy="-1.5708 -2.22045e-16 3.14159"/>
      <geometry>
        <box size="0.0354 0.0504 0.0353"/>
      </geometry>
    </collision>
    <collision>
      <origin xyz="0.018 0.046375 0.0205" rpy="3.14159 -1.22465e-16 1.5708"/>
      <geometry>
        <box size="0.04 0.0609 0.0408"/>
      </geometry>
    </collision>
    <collision>
      <origin xyz="2.77556e-18 0.046375 0.1465" rpy="-1.5708 -2.22045e-16 -3.4451e-16"/>
      <geometry>
        <box size="0.0354 0.0504 0.0353"/>
      </geometry>
    </collision>
    <collision>
      <origin xyz="0.013373 2.77556e-18 0.16193" rpy="0 -0 1.5708"/>
      <geometry>
        <box size="0.0354 0.0504 0.0353"/>
      </geometry>
    </collision>
  </link>

  <!-- Component mx64_u_arm#2 -->

  <link name="right_hip_yaw">
    <visual>
      <geometry>
        <mesh filename="package://urdf/ec37fb5994935cac6b903c383fe7bf300d33ef4f.stl"/>
      </geometry>
      <material name="mx64_u_arm_mx64_u_arm_2_0_material">
        <color rgba="0.8 0.8 0.8 1.0"/>
      </material>
      <origin xyz="3.67441e-34 3.00039e-18 -0.0245" rpy="-3.14159 -5.35312e-24 4.37114e-08"/>
    </visual>
    <visual>
      <geometry>
        <mesh filename="package://urdf/40e2500861f63fa0d75c3dd3c8fdd0ec8d70ece5.stl"/>
      </geometry>
      <material name="mx64_u_arm_mx64_u_2_1_material">
        <color rgba="0.8 0.8 0.8 1.0"/>
      </material>
      <origin xyz="3.67441e-34 3.00039e-18 -0.0245" rpy="-3.14159 -5.35312e-24 4.37114e-08"/>
    </visual>
    <inertial>
      <origin xyz="-0.000506838 -2.21546e-11 -0.0373359" rpy="0 0 0"/>
      <mass value="0.032317"/>
      <inertia ixx="8.54961e-06"  ixy="-8.88178e-24"  ixz="-2.83665e-09" iyy="2.08698e-05" iyz="-5.68434e-23" izz="1.69968e-05" />
    </inertial>
    <collision>
      <origin xyz="-0.0245 -1.07093e-09 -0.0395" rpy="-3.14159 -5.35312e-24 4.37114e-08"/>
      <geometry>
        <box size="0.0018 0.0298 0.0298"/>
      </geometry>
    </collision>
    <collision>
      <origin xyz="-0.0245 -1.07093e-09 -0.0545" rpy="-3.14159 -1.5708 0"/>
      <geometry>
        <cylinder radius="0.0148" length="0.0018"/>
      </geometry>
    </collision>
    <collision>
      <origin xyz="0.0245 1.07093e-09 -0.0395" rpy="-3.14159 -5.35312e-24 4.37114e-08"/>
      <geometry>
        <box size="0.0018 0.0298 0.0298"/>
      </geometry>
    </collision>
    <collision>
      <origin xyz="0.0245 1.07093e-09 -0.0545" rpy="-3.14159 -1.5708 0"/>
      <geometry>
        <cylinder radius="0.0148" length="0.0018"/>
      </geometry>
    </collision>
    <collision>
      <origin xyz="3.67441e-34 3.00039e-18 -0.0245" rpy="-3.14159 -5.35312e-24 4.37114e-08"/>
      <geometry>
        <box size="0.0508 0.0298 0.0018"/>
      </geometry>
    </collision>
  </link>
  <joint name="right_hip_yaw" type="revolute">
    <parent link="trunk"/>
    <child link="right_hip_yaw"/>
    <axis xyz="0 0 1"/>
    <origin xyz="0 -0.046375 0.0205" rpy="0 -0 0"/>
    <limit effort="6.4" velocity="14" lower="-3.14159" upper="3.14159"/>
  </joint>

  <!-- Component mx64_block#3 -->

  <link name="right_hip_roll">
    <visual>
      <geometry>
        <mesh filename="package://urdf/ca50ae7d456653e15dfc15ff54aabe7e237591c9.stl"/>
      </geometry>
      <material name="mx64_block_mx64_block_3_0_material">
        <color rgba="0.8 0.8 0.8 1.0"/>
      </material>
      <origin xyz="-0.047 -2.05444e-09 1.04361e-17" rpy="-3.14159 -1.5708 0"/>
    </visual>
    <visual>
      <geometry>
        <mesh filename="package://urdf/ec48c503b08df80db4b69bdca79c3c4abd9a9f79.stl"/>
      </geometry>
      <material name="mx64_block_mx64_3_1_material">
        <color rgba="0.15 0.2 0.15 1.0"/>
      </material>
      <origin xyz="-0.047 -2.05444e-09 1.04361e-17" rpy="-3.14159 -1.5708 0"/>
    </visual>
    <visual>
      <geometry>
        <mesh filename="package://urdf/25b260d037c322d47acdc54ca73d53b468bfe2d1.stl"/>
      </geometry>
      <material name="mx64_block_mx64_arm_3_2_material">
        <color rgba="0.5 0.5 0.5 1.0"/>
      </material>
      <origin xyz="-0.0265 -1.15835e-09 5.88419e-18" rpy="-3.14159 -1.5708 0"/>
    </visual>
    <visual>
      <geometry>
        <mesh filename="package://urdf/25b260d037c322d47acdc54ca73d53b468bfe2d1.stl"/>
      </geometry>
      <material name="mx64_block_mx64_arm_3_3_material">
        <color rgba="0.5 0.5 0.5 1.0"/>
      </material>
      <origin xyz="-0.0705 -3.08165e-09 1.56542e-17" rpy="-3.14159 -1.5708 0"/>
    </visual>
    <visual>
      <geometry>
        <mesh filename="package://urdf/f14dd39e029f8996e3026773ee23983bf9c6aaf9.stl"/>
      </geometry>
      <material name="mx64_block_tag_3_4_material">
        <color rgba="0.9 0.9 0.9 1.0"/>
      </material>
      <origin xyz="-0.0265 -1.15835e-09 -0.035" rpy="-1.5708 -9.958e-17 -1.5708"/>
    </visual>
    <visual>
      <geometry>
        <mesh filename="package://urdf/ec48c503b08df80db4b69bdca79c3c4abd9a9f79.stl"/>
      </geometry>
      <material name="mx64_block_mx64_3_5_material">
        <color rgba="0.15 0.2 0.15 1.0"/>
      </material>
      <origin xyz="0 0 0" rpy="-1.5708 -1.5708 0"/>
    </visual>
    <visual>
      <geometry>
        <mesh filename="package://urdf/25b260d037c322d47acdc54ca73d53b468bfe2d1.stl"/>
      </geometry>
      <material name="mx64_block_mx64_arm_3_6_material">
        <color rgba="0.5 0.5 0.5 1.0"/>
      </material>
      <origin xyz="-8.96083e-10 0.0205 2.51053e-18" rpy="-1.5708 -1.5708 0"/>
    </visual>
    <visual>
      <geometry>
        <mesh filename="package://urdf/25b260d037c322d47acdc54ca73d53b468bfe2d1.stl"/>
      </geometry>
      <material name="mx64_block_mx64_arm_3_7_material">
        <color rgba="0.5 0.5 0.5 1.0"/>
      </material>
      <origin xyz="1.02722e-09 -0.0235 -2.87793e-18" rpy="-1.5708 -1.5708 0"/>
    </visual>
    <visual>
      <geometry>
        <mesh filename="package://urdf/f14dd39e029f8996e3026773ee23983bf9c6aaf9.stl"/>
      </geometry>
      <material name="mx64_block_tag_3_8_material">
        <color rgba="0.9 0.9 0.9 1.0"/>
      </material>
      <origin xyz="-8.96083e-10 0.0205 -0.035" rpy="-1.5708 -5.35312e-24 4.37114e-08"/>
    </visual>
    <visual>
      <geometry>
        <mesh filename="package://urdf/25b260d037c322d47acdc54ca73d53b468bfe2d1.stl"/>
      </geometry>
      <material name="mx64_block_mx64_arm_3_9_material">
        <color rgba="0.5 0.5 0.5 1.0"/>
      </material>
      <origin xyz="0.0201 8.78599e-10 -4.4631e-18" rpy="-3.14159 -1.5708 0"/>
    </visual>
    <inertial>
      <origin xyz="-0.0225454 -0.000152445 -0.0139042" rpy="0 0 0"/>
      <mass value="0.288805"/>
      <inertia ixx="0.000257701"  ixy="-3.42917e-07"  ixz="-4.10246e-06" iyy="0.000293035" iyz="-9.92596e-07" izz="0.000121563" />
    </inertial>
    <collision>
      <origin xyz="-0.047 -2.05444e-09 -0.018" rpy="-1.5708 -9.958e-17 -1.5708"/>
      <geometry>
        <box size="0.04 0.0609 0.0408"/>
      </geometry>
    </collision>
    <collision>
      <origin xyz="0 2.20437e-18 -0.018" rpy="-1.5708 -5.35312e-24 4.37114e-08"/>
      <geometry>
        <box size="0.04 0.0609 0.0408"/>
      </geometry>
    </collision>
  </link>
  <joint name="right_hip_roll" type="revolute">
    <parent link="right_hip_yaw"/>
    <child link="right_hip_roll"/>
    <axis xyz="1 0 0"/>
    <origin xyz="8.17369e-34 6.67434e-18 -0.0545" rpy="-1.05083e-32 -0 0"/>
    <limit effort="6.4" velocity="14" lower="-3.14159" upper="3.14159"/>
  </joint>

  <!-- Component mx64_u_arm_to_side#4 -->

  <link name="right_hip_pitch">
    <visual>
      <geometry>
        <mesh filename="package://urdf/e2b6cfe73e1fd2427ccfcbdf9c5c458af0d985e7.stl"/>
      </geometry>
      <material name="mx64_u_arm_to_side_mx64_u_arm_to_side_4_0_material">
        <color rgba="0.8 0.8 0.8 1.0"/>
      </material>
      <origin xyz="4.2796e-16 -1.03946e-08 -0.1189" rpy="-2.22045e-16 -8.74228e-08 -1.5708"/>
    </visual>
    <visual>
      <geometry>
        <mesh filename="package://urdf/ec48c503b08df80db4b69bdca79c3c4abd9a9f79.stl"/>
      </geometry>
      <material name="mx64_u_arm_to_side_mx64_4_1_material">
        <color rgba="0.15 0.2 0.15 1.0"/>
      </material>
      <origin xyz="5.03906e-16 -1.22392e-08 -0.14" rpy="1.5708 2.22045e-16 4.37114e-08"/>
    </visual>
    <visual>
      <geometry>
        <mesh filename="package://urdf/25b260d037c322d47acdc54ca73d53b468bfe2d1.stl"/>
      </geometry>
      <material name="mx64_u_arm_to_side_mx64_arm_4_2_material">
        <color rgba="0.5 0.5 0.5 1.0"/>
      </material>
      <origin xyz="8.96084e-10 -0.0205 -0.14" rpy="1.5708 2.22045e-16 4.37114e-08"/>
    </visual>
    <visual>
      <geometry>
        <mesh filename="package://urdf/25b260d037c322d47acdc54ca73d53b468bfe2d1.stl"/>
      </geometry>
      <material name="mx64_u_arm_to_side_mx64_arm_4_3_material">
        <color rgba="0.5 0.5 0.5 1.0"/>
      </material>
      <origin xyz="-1.02722e-09 0.0235 -0.14" rpy="1.5708 2.22045e-16 4.37114e-08"/>
    </visual>
    <visual>
      <geometry>
        <mesh filename="package://urdf/f14dd39e029f8996e3026773ee23983bf9c6aaf9.stl"/>
      </geometry>
      <material name="mx64_u_arm_to_side_tag_4_4_material">
        <color rgba="0.9 0.9 0.9 1.0"/>
      </material>
      <origin xyz="-0.035 -0.0205 -0.14" rpy="1.5708 -1.5708 0"/>
    </visual>
    <visual>
      <geometry>
        <mesh filename="package://urdf/6be08d8e010e5839886db14da5a6263c941ff1bc.stl"/>
      </geometry>
      <material name="mx64_u_arm_to_side_mx64_u_4_5_material">
        <color rgba="0.8 0.8 0.8 1.0"/>
      </material>
      <origin xyz="4.2796e-16 -1.03946e-08 -0.1189" rpy="-2.22045e-16 -8.74228e-08 -1.5708"/>
    </visual>
    <inertial>
      <origin xyz="-0.00917061 0.000379397 -0.113155" rpy="0 0 0"/>
      <mass value="0.218939"/>
      <inertia ixx="0.000492068"  ixy="4.92539e-07"  ixz="7.08778e-07" iyy="0.000504914" iyz="-5.38995e-05" izz="0.000121477" />
    </inertial>
    <collision>
      <origin xyz="-1.07093e-09 0.0245 -0.05945" rpy="-2.22045e-16 -8.74228e-08 -1.5708"/>
      <geometry>
        <box size="0.0018 0.0298 0.1187"/>
      </geometry>
    </collision>
    <collision>
      <origin xyz="-1.07093e-09 0.0245 -2.14186e-09" rpy="1.5708 1.5708 0"/>
      <geometry>
        <cylinder radius="0.0148" length="0.0018"/>
      </geometry>
    </collision>
    <collision>
      <origin xyz="1.07093e-09 -0.0245 -0.05945" rpy="-2.22045e-16 -8.74228e-08 -1.5708"/>
      <geometry>
        <box size="0.0018 0.0298 0.1187"/>
      </geometry>
    </collision>
    <collision>
      <origin xyz="1.07093e-09 -0.0245 2.14186e-09" rpy="1.5708 1.5708 0"/>
      <geometry>
        <cylinder radius="0.0148" length="0.0018"/>
      </geometry>
    </collision>
    <collision>
      <origin xyz="4.2796e-16 -1.03946e-08 -0.1189" rpy="-2.22045e-16 -8.74228e-08 -1.5708"/>
      <geometry>
        <box size="0.0508 0.0298 0.0018"/>
      </geometry>
    </collision>
    <collision>
      <origin xyz="-0.018 -1.3026e-08 -0.14" rpy="1.5708 -1.5708 0"/>
      <geometry>
        <box size="0.04 0.0609 0.0408"/>
      </geometry>
    </collision>
  </link>
  <joint name="right_hip_pitch" type="revolute">
    <parent link="right_hip_roll"/>
    <child link="right_hip_pitch"/>
    <axis xyz="0 1 0"/>
    <origin xyz="0 0 0" rpy="0 -1.85711e-32 0"/>
    <limit effort="6.4" velocity="14" lower="-3.14159" upper="3.14159"/>
  </joint>

  <!-- Component mx64_arms#5 -->

  <link name="right_knee">
    <visual>
      <geometry>
        <mesh filename="package://urdf/5495ce21c8f75def8d90084449f801701d8a1dc9.stl"/>
      </geometry>
      <material name="mx64_arms_mx64_arms_5_0_material">
        <color rgba="0.8 0.8 0.8 1.0"/>
      </material>
      <origin xyz="-3.0598e-09 -6.11959e-09 -0.07" rpy="1.5708 -1.5708 0"/>
    </visual>
    <visual>
      <geometry>
        <mesh filename="package://urdf/c8cae62de47e73927ee995fa8e8e73b00b45320a.stl"/>
      </geometry>
      <material name="mx64_arms_mx64_arms_plate_5_1_material">
        <color rgba="0.8 0.8 0.8 1.0"/>
      </material>
      <origin xyz="-2.03258e-09 -0.0235 -0.07" rpy="1.5708 -1.5708 0"/>
    </visual>
    <visual>
      <geometry>
        <mesh filename="package://urdf/c8cae62de47e73927ee995fa8e8e73b00b45320a.stl"/>
      </geometry>
      <material name="mx64_arms_mx64_arms_plate_5_2_material">
        <color rgba="0.8 0.8 0.8 1.0"/>
      </material>
      <origin xyz="-4.21815e-09 0.0265 -0.07" rpy="1.5708 -1.5708 0"/>
    </visual>
    <inertial>
      <origin xyz="-3.08493e-09 0.000499994 -0.070075" rpy="0 0 0"/>
      <mass value="0.078404"/>
      <inertia ixx="5.40315e-05"  ixy="-9.09495e-22"  ixz="1.06581e-23" iyy="0.000230305" iyz="0" izz="0.000186293" />
    </inertial>
    <collision>
      <origin xyz="-1.98887e-09 -0.0245 -0.07" rpy="1.5708 -1.5708 0"/>
      <geometry>
        <box size="0.1728 0.0278 0.0018"/>
      </geometry>
    </collision>
    <collision>
      <origin xyz="-4.17444e-09 0.0255 -0.07" rpy="1.5708 -1.5708 0"/>
      <geometry>
        <box size="0.1728 0.0278 0.0018"/>
      </geometry>
    </collision>
  </link>
  <joint name="right_knee" type="revolute">
    <parent link="right_hip_pitch"/>
    <child link="right_knee"/>
    <axis xyz="0 1 0"/>
    <origin xyz="5.03906e-16 -1.22392e-08 -0.14" rpy="0 -0 -6.61744e-24"/>
    <limit effort="6.4" velocity="14" lower="-3.14159" upper="3.14159"/>
  </joint>

  <!-- Component mx64_block#6 -->

  <link name="right_ankle_pitch">
    <visual>
      <geometry>
        <mesh filename="package://urdf/ca50ae7d456653e15dfc15ff54aabe7e237591c9.stl"/>
      </geometry>
      <material name="mx64_block_mx64_block_6_0_material">
        <color rgba="0.8 0.8 0.8 1.0"/>
      </material>
      <origin xyz="-0.047 -2.05444e-09 -2.05444e-09" rpy="-4.37114e-08 1.5708 0"/>
    </visual>
    <visual>
      <geometry>
        <mesh filename="package://urdf/ec48c503b08df80db4b69bdca79c3c4abd9a9f79.stl"/>
      </geometry>
      <material name="mx64_block_mx64_6_1_material">
        <color rgba="0.15 0.2 0.15 1.0"/>
      </material>
      <origin xyz="-0.047 -2.05444e-09 -2.05444e-09" rpy="-4.37114e-08 1.5708 0"/>
    </visual>
    <visual>
      <geometry>
        <mesh filename="package://urdf/25b260d037c322d47acdc54ca73d53b468bfe2d1.stl"/>
      </geometry>
      <material name="mx64_block_mx64_arm_6_2_material">
        <color rgba="0.5 0.5 0.5 1.0"/>
      </material>
      <origin xyz="-0.0265 -1.15835e-09 -1.15835e-09" rpy="-4.37114e-08 1.5708 0"/>
    </visual>
    <visual>
      <geometry>
        <mesh filename="package://urdf/25b260d037c322d47acdc54ca73d53b468bfe2d1.stl"/>
      </geometry>
      <material name="mx64_block_mx64_arm_6_3_material">
        <color rgba="0.5 0.5 0.5 1.0"/>
      </material>
      <origin xyz="-0.0705 -3.08165e-09 -3.08165e-09" rpy="-4.37114e-08 1.5708 0"/>
    </visual>
    <visual>
      <geometry>
        <mesh filename="package://urdf/f14dd39e029f8996e3026773ee23983bf9c6aaf9.stl"/>
      </geometry>
      <material name="mx64_block_tag_6_4_material">
        <color rgba="0.9 0.9 0.9 1.0"/>
      </material>
      <origin xyz="-0.0265 1.90145e-09 0.035" rpy="1.5708 8.74228e-08 1.5708"/>
    </visual>
    <visual>
      <geometry>
        <mesh filename="package://urdf/ec48c503b08df80db4b69bdca79c3c4abd9a9f79.stl"/>
      </geometry>
      <material name="mx64_block_mx64_6_5_material">
        <color rgba="0.15 0.2 0.15 1.0"/>
      </material>
      <origin xyz="0 0 0" rpy="1.5708 1.5708 0"/>
    </visual>
    <visual>
      <geometry>
        <mesh filename="package://urdf/25b260d037c322d47acdc54ca73d53b468bfe2d1.stl"/>
      </geometry>
      <material name="mx64_block_mx64_arm_6_6_material">
        <color rgba="0.5 0.5 0.5 1.0"/>
      </material>
      <origin xyz="8.96083e-10 -0.0205 1.79217e-09" rpy="1.5708 1.5708 0"/>
    </visual>
    <visual>
      <geometry>
        <mesh filename="package://urdf/25b260d037c322d47acdc54ca73d53b468bfe2d1.stl"/>
      </geometry>
      <material name="mx64_block_mx64_arm_6_7_material">
        <color rgba="0.5 0.5 0.5 1.0"/>
      </material>
      <origin xyz="-1.02722e-09 0.0235 -2.05444e-09" rpy="1.5708 1.5708 0"/>
    </visual>
    <visual>
      <geometry>
        <mesh filename="package://urdf/f14dd39e029f8996e3026773ee23983bf9c6aaf9.stl"/>
      </geometry>
      <material name="mx64_block_tag_6_8_material">
        <color rgba="0.9 0.9 0.9 1.0"/>
      </material>
      <origin xyz="-6.33815e-10 -0.0205 0.035" rpy="1.5708 -4.37114e-08 4.37114e-08"/>
    </visual>
    <visual>
      <geometry>
        <mesh filename="package://urdf/25b260d037c322d47acdc54ca73d53b468bfe2d1.stl"/>
      </geometry>
      <material name="mx64_block_mx64_arm_6_9_material">
        <color rgba="0.5 0.5 0.5 1.0"/>
      </material>
      <origin xyz="0.0201 8.78599e-10 8.78599e-10" rpy="-4.37114e-08 1.5708 0"/>
    </visual>
    <inertial>
      <origin xyz="-0.0225454 0.000152444 0.0139042" rpy="0 0 0"/>
      <mass value="0.288805"/>
      <inertia ixx="0.000257701"  ixy="-3.42917e-07"  ixz="-4.10246e-06" iyy="0.000293035" iyz="-9.92596e-07" izz="0.000121563" />
    </inertial>
    <collision>
      <origin xyz="-0.047 -4.80825e-10 0.018" rpy="1.5708 8.74228e-08 1.5708"/>
      <geometry>
        <box size="0.04 0.0609 0.0408"/>
      </geometry>
    </collision>
    <collision>
      <origin xyz="-7.86805e-10 1.57361e-09 0.018" rpy="1.5708 -4.37114e-08 4.37114e-08"/>
      <geometry>
        <box size="0.04 0.0609 0.0408"/>
      </geometry>
    </collision>
  </link>
  <joint name="right_ankle_pitch" type="revolute">
    <parent link="right_knee"/>
    <child link="right_ankle_pitch"/>
    <axis xyz="0 1 0"/>
    <origin xyz="-6.11959e-09 -1.22392e-08 -0.14" rpy="0 -7.57953e-26 -6.61744e-24"/>
    <limit effort="6.4" velocity="14" lower="-3.14159" upper="3.14159"/>
  </joint>

  <!-- Component mx64_foot#7 -->

  <link name="right_ankle_roll">
    <visual>
      <geometry>
        <mesh filename="package://urdf/b570f1dace5ba35e1dc259612eb8c663b9c68a00.stl"/>
      </geometry>
      <material name="mx64_foot_mx64_foot_7_0_material">
        <color rgba="0.8 0.8 0.8 1.0"/>
      </material>
      <origin xyz="1.31134e-09 -2.62268e-09 -0.03" rpy="-8.74228e-08 -4.37114e-08 4.37114e-08"/>
    </visual>
    <visual>
      <geometry>
        <mesh filename="package://urdf/3e78e2aa8de18b5f0e80d8ac55b396534b0ad6af.stl"/>
      </geometry>
      <material name="mx64_foot_mx64_u_7_1_material">
        <color rgba="0.8 0.8 0.8 1.0"/>
      </material>
      <origin xyz="1.31134e-09 -2.62268e-09 -0.03" rpy="-8.74228e-08 -4.37114e-08 4.37114e-08"/>
    </visual>
    <visual>
      <geometry>
        <mesh filename="package://urdf/5b4db288fcc39ad3a7f74e9372d0e217496d93d2.stl"/>
      </geometry>
      <material name="mx64_foot_foot_7_2_material">
        <color rgba="0.8 0.8 0.8 1.0"/>
      </material>
      <origin xyz="1.61732e-09 -0.005 -0.032" rpy="-8.74228e-08 -4.37114e-08 4.37114e-08"/>
    </visual>
    <inertial>
      <origin xyz="-8.32524e-05 -0.00416746 -0.0354118" rpy="0 0 0"/>
      <mass value="0.196741"/>
      <inertia ixx="0.000178374"  ixy="6.82609e-08"  ixz="2.96051e-07" iyy="0.000499794" iyz="-2.96051e-06" izz="0.000608649" />
    </inertial>
    <collision>
      <origin xyz="-0.0245 -2.38227e-09 -0.015" rpy="-8.74228e-08 -4.37114e-08 4.37114e-08"/>
      <geometry>
        <box size="0.0018 0.0298 0.0298"/>
      </geometry>
    </collision>
    <collision>
      <origin xyz="-0.0245 -1.07093e-09 -1.07093e-09" rpy="-4.37114e-08 1.5708 0"/>
      <geometry>
        <cylinder radius="0.0148" length="0.0018"/>
      </geometry>
    </collision>
    <collision>
      <origin xyz="0.0245 -2.40413e-10 -0.015" rpy="-8.74228e-08 -4.37114e-08 4.37114e-08"/>
      <geometry>
        <box size="0.0018 0.0298 0.0298"/>
      </geometry>
    </collision>
    <collision>
      <origin xyz="0.0245 1.07093e-09 1.07093e-09" rpy="-4.37114e-08 1.5708 0"/>
      <geometry>
        <cylinder radius="0.0148" length="0.0018"/>
      </geometry>
    </collision>
    <collision>
      <origin xyz="1.31134e-09 -2.62268e-09 -0.03" rpy="-8.74228e-08 -4.37114e-08 4.37114e-08"/>
      <geometry>
        <box size="0.0508 0.0298 0.0018"/>
      </geometry>
    </collision>
    <collision>
      <origin xyz="1.61732e-09 -0.005 -0.032" rpy="-8.74228e-08 -4.37114e-08 4.37114e-08"/>
      <geometry>
        <box size="0.1418 0.0818 0.0018"/>
      </geometry>
    </collision>
    <collision>
      <origin xyz="-0.066 -0.041 -0.0395" rpy="-8.74228e-08 -4.37114e-08 4.37114e-08"/>
      <geometry>
        <cylinder radius="0.0048" length="0.0148"/>
      </geometry>
    </collision>
    <collision>
      <origin xyz="-0.066 -0.041 -0.053" rpy="-8.74228e-08 -4.37114e-08 4.37114e-08"/>
      <geometry>
        <sphere radius="0.0088"/>
      </geometry>
    </collision>
    <collision>
      <origin xyz="-0.066 0.031 -0.0395" rpy="-8.74228e-08 -4.37114e-08 4.37114e-08"/>
      <geometry>
        <cylinder radius="0.0048" length="0.0148"/>
      </geometry>
    </collision>
    <collision>
      <origin xyz="-0.066 0.031 -0.053" rpy="-8.74228e-08 -4.37114e-08 4.37114e-08"/>
      <geometry>
        <sphere radius="0.0088"/>
      </geometry>
    </collision>
    <collision>
      <origin xyz="0.066 -0.041 -0.0395" rpy="-8.74228e-08 -4.37114e-08 4.37114e-08"/>
      <geometry>
        <cylinder radius="0.0048" length="0.0148"/>
      </geometry>
    </collision>
    <collision>
      <origin xyz="0.066 -0.041 -0.053" rpy="-8.74228e-08 -4.37114e-08 4.37114e-08"/>
      <geometry>
        <sphere radius="0.0088"/>
      </geometry>
    </collision>
    <collision>
      <origin xyz="0.066 0.031 -0.0395" rpy="-8.74228e-08 -4.37114e-08 4.37114e-08"/>
      <geometry>
        <cylinder radius="0.0048" length="0.0148"/>
      </geometry>
    </collision>
    <collision>
      <origin xyz="0.066 0.031 -0.053" rpy="-8.74228e-08 -4.37114e-08 4.37114e-08"/>
      <geometry>
        <sphere radius="0.0088"/>
      </geometry>
    </collision>
  </link>
  <joint name="right_ankle_roll" type="revolute">
    <parent link="right_ankle_pitch"/>
    <child link="right_ankle_roll"/>
    <axis xyz="1 0 0"/>
    <origin xyz="0 0 0" rpy="1.83244e-25 6.61744e-24 -6.61744e-24"/>
    <limit effort="6.4" velocity="14" lower="-3.14159" upper="3.14159"/>
  </joint>
  <link name="right_foot_tip">
    <inertial>
      <origin xyz="0 0 0" rpy="0 0 0" />
      <mass value="0" />
      <inertia ixx="0" ixy="0" ixz="0" iyy="0" iyz="0" izz="0" />
    </inertial>
  </link>
  <joint name="right_foot_tip" type="fixed">
    <origin xyz="2.66639e-09 -5.33279e-09 -0.061" rpy="-8.74228e-08 -4.37114e-08 4.37114e-08"/>
    <parent link="right_ankle_roll" />
    <child link="right_foot_tip" />
    <axis xyz="0 0 0" />
  </joint>

  <!-- Component mx28_u_arm#8 -->

  <link name="right_shoulder_pitch">
    <visual>
      <geometry>
        <mesh filename="package://urdf/9c1012ad5d1ae82ddba70bad79a3843487f16b4f.stl"/>
      </geometry>
      <material name="mx28_u_arm_mx28_u_arm_8_0_material">
        <color rgba="0.8 0.8 0.8 1.0"/>
      </material>
      <origin xyz="-4.82948e-18 -0.02175 -4.82948e-18" rpy="1.5708 -2.22045e-16 -2.22045e-16"/>
    </visual>
    <visual>
      <geometry>
        <mesh filename="package://urdf/194815b7aa6504c4310c5fff46b0aa33332a958f.stl"/>
      </geometry>
      <material name="mx28_u_arm_mx28_u_8_1_material">
        <color rgba="0.8 0.8 0.8 1.0"/>
      </material>
      <origin xyz="-4.82948e-18 -0.02175 -4.82948e-18" rpy="1.5708 -2.22045e-16 -2.22045e-16"/>
    </visual>
    <inertial>
      <origin xyz="-7.34356e-18 -0.0330724 -7.34356e-18" rpy="0 0 0"/>
      <mass value="0.029002"/>
      <inertia ixx="6.48424e-06"  ixy="0"  ixz="0" iyy="1.49472e-05" iyz="8.88178e-24" izz="1.26475e-05" />
    </inertial>
    <collision>
      <origin xyz="-0.02175 -0.03425 -1.24345e-17" rpy="1.5708 -2.22045e-16 -2.22045e-16"/>
      <geometry>
        <box size="0.0018 0.0298 0.0248"/>
      </geometry>
    </collision>
    <collision>
      <origin xyz="-0.02175 -0.04675 -1.52101e-17" rpy="1.5708 -2.22045e-16 1.5708"/>
      <geometry>
        <cylinder radius="0.0148" length="0.0018"/>
      </geometry>
    </collision>
    <collision>
      <origin xyz="0.02175 -0.03425 -2.77556e-18" rpy="1.5708 -2.22045e-16 -2.22045e-16"/>
      <geometry>
        <box size="0.0018 0.0298 0.0248"/>
      </geometry>
    </collision>
    <collision>
      <origin xyz="0.02175 -0.04675 -5.55113e-18" rpy="1.5708 -2.22045e-16 1.5708"/>
      <geometry>
        <cylinder radius="0.0148" length="0.0018"/>
      </geometry>
    </collision>
    <collision>
      <origin xyz="-4.82948e-18 -0.02175 -4.82948e-18" rpy="1.5708 -2.22045e-16 -2.22045e-16"/>
      <geometry>
        <box size="0.0453 0.0298 0.0018"/>
      </geometry>
    </collision>
  </link>
  <joint name="right_shoulder_pitch" type="revolute">
    <parent link="trunk"/>
    <child link="right_shoulder_pitch"/>
    <axis xyz="0 1 0"/>
    <origin xyz="0 -0.046375 0.159" rpy="0 -0 0"/>
    <limit effort="2.8" velocity="12" lower="-3.14159" upper="3.14159"/>
  </joint>

  <!-- Component mx28_u_l#9 -->

  <link name="right_shoulder_roll">
    <visual>
      <geometry>
        <mesh filename="package://urdf/5cd934a01ca249c0e5600e30ff006441d57cb7a3.stl"/>
      </geometry>
      <material name="mx28_u_l_mx28_u_l_9_0_material">
        <color rgba="0.8 0.8 0.8 1.0"/>
      </material>
      <origin xyz="8.50432e-18 1.67415e-09 -0.0383" rpy="-2.22045e-16 -4.37114e-08 1.5708"/>
    </visual>
    <visual>
      <geometry>
        <mesh filename="package://urdf/e9f087865029fcd254bd6913f6f702b6f701e249.stl"/>
      </geometry>
      <material name="mx28_u_l_mx28_9_1_material">
        <color rgba="0.15 0.2 0.15 1.0"/>
      </material>
      <origin xyz="0 0 0" rpy="3.14159 -1.5708 0"/>
    </visual>
    <visual>
      <geometry>
        <mesh filename="package://urdf/f3516f363c4dfdeb49895426ad64acab9d85cee8.stl"/>
      </geometry>
      <material name="mx28_u_l_mx28_arm_9_2_material">
        <color rgba="0.5 0.5 0.5 1.0"/>
      </material>
      <origin xyz="0.01775 -7.8826e-18 7.10543e-18" rpy="3.14159 -1.5708 0"/>
    </visual>
    <visual>
      <geometry>
        <mesh filename="package://urdf/f3516f363c4dfdeb49895426ad64acab9d85cee8.stl"/>
      </geometry>
      <material name="mx28_u_l_mx28_arm_9_3_material">
        <color rgba="0.5 0.5 0.5 1.0"/>
      </material>
      <origin xyz="-0.02075 9.21487e-18 -7.10543e-18" rpy="3.14159 -1.5708 0"/>
    </visual>
    <visual>
      <geometry>
        <mesh filename="package://urdf/f14dd39e029f8996e3026773ee23983bf9c6aaf9.stl"/>
      </geometry>
      <material name="mx28_u_l_tag_9_4_material">
        <color rgba="0.9 0.9 0.9 1.0"/>
      </material>
      <origin xyz="0.01775 1.09278e-09 -0.025" rpy="-1.5708 4.37114e-08 -1.5708"/>
    </visual>
    <visual>
      <geometry>
        <mesh filename="package://urdf/a0a3e3041c2350bb54d06f6cc9aaf2cf28ae6be3.stl"/>
      </geometry>
      <material name="mx28_u_l_mx28_l_9_5_material">
        <color rgba="0.8 0.8 0.8 1.0"/>
      </material>
      <origin xyz="8.50432e-18 1.67415e-09 -0.0383" rpy="-2.22045e-16 -4.37114e-08 1.5708"/>
    </visual>
    <visual>
      <geometry>
        <mesh filename="package://urdf/024ff0622d27b0e34823812b1f294c7b27defa57.stl"/>
      </geometry>
      <material name="mx28_u_l_mx28_u_9_6_material">
        <color rgba="0.8 0.8 0.8 1.0"/>
      </material>
      <origin xyz="-0.0178 3.4838e-09 -0.0797" rpy="1.5708 -4.37114e-08 1.5708"/>
    </visual>
    <inertial>
      <origin xyz="-0.00345419 1.50736e-09 -0.0344843" rpy="0 0 0"/>
      <mass value="0.141734"/>
      <inertia ixx="0.00017908"  ixy="1.77636e-24"  ixz="1.06901e-20" iyy="0.000177275" iyz="1.74732e-05" izz="4.7689e-05" />
    </inertial>
    <collision>
      <origin xyz="-0.002 1.67415e-09 -0.0383" rpy="-2.22045e-16 -4.37114e-08 1.5708"/>
      <geometry>
        <box size="0.0354 0.0374 0.0018"/>
      </geometry>
    </collision>
    <collision>
      <origin xyz="-0.0198 2.90681e-09 -0.0665" rpy="-2.22045e-16 -4.37114e-08 1.5708"/>
      <geometry>
        <box size="0.0354 0.0018 0.0562"/>
      </geometry>
    </collision>
    <collision>
      <origin xyz="-0.0028 -0.02175 -0.0797" rpy="1.5708 -4.37114e-08 1.5708"/>
      <geometry>
        <box size="0.0018 0.0298 0.0298"/>
      </geometry>
    </collision>
    <collision>
      <origin xyz="0.0122 -0.02175 -0.0797" rpy="1.5708 4.4409e-16 3.14159"/>
      <geometry>
        <cylinder radius="0.0148" length="0.0018"/>
      </geometry>
    </collision>
    <collision>
      <origin xyz="-0.0028 0.02175 -0.0797" rpy="1.5708 -4.37114e-08 1.5708"/>
      <geometry>
        <box size="0.0018 0.0298 0.0298"/>
      </geometry>
    </collision>
    <collision>
      <origin xyz="0.0122 0.02175 -0.0797" rpy="1.5708 4.4409e-16 3.14159"/>
      <geometry>
        <cylinder radius="0.0148" length="0.0018"/>
      </geometry>
    </collision>
    <collision>
      <origin xyz="-0.0178 3.4838e-09 -0.0797" rpy="1.5708 -4.37114e-08 1.5708"/>
      <geometry>
        <box size="0.0453 0.0298 0.0018"/>
      </geometry>
    </collision>
    <collision>
      <origin xyz="2.77556e-18 5.46392e-10 -0.0125" rpy="-1.5708 4.37114e-08 -1.5708"/>
      <geometry>
        <box size="0.0354 0.0504 0.0353"/>
      </geometry>
    </collision>
  </link>
  <joint name="right_shoulder_roll" type="revolute">
    <parent link="right_shoulder_pitch"/>
    <child link="right_shoulder_roll"/>
    <axis xyz="1 0 0"/>
    <origin xyz="-1.03806e-17 -0.04675 -1.03806e-17" rpy="-9.8608e-32 -0 -9.86076e-32"/>
    <limit effort="2.8" velocity="12" lower="-3.14159" upper="3.14159"/>
  </joint>

  <!-- Component mx28_elbow#10 -->

  <link name="right_elbow">
    <visual>
      <geometry>
        <mesh filename="package://urdf/329dbba1976866b0cd7b0f2bdf9a6c14725749b6.stl"/>
      </geometry>
      <material name="mx28_elbow_mx28_elbow_10_0_material">
        <color rgba="0.8 0.8 0.8 1.0"/>
      </material>
      <origin xyz="1.67415e-09 1.67415e-09 -0.0383" rpy="4.37114e-08 -4.37114e-08 8.74228e-08"/>
    </visual>
    <visual>
      <geometry>
        <mesh filename="package://urdf/e9f087865029fcd254bd6913f6f702b6f701e249.stl"/>
      </geometry>
      <material name="mx28_elbow_mx28_10_1_material">
        <color rgba="0.15 0.2 0.15 1.0"/>
      </material>
      <origin xyz="0 0 0" rpy="1.5708 -1.5708 0"/>
    </visual>
    <visual>
      <geometry>
        <mesh filename="package://urdf/f3516f363c4dfdeb49895426ad64acab9d85cee8.stl"/>
      </geometry>
      <material name="mx28_elbow_mx28_arm_10_2_material">
        <color rgba="0.5 0.5 0.5 1.0"/>
      </material>
      <origin xyz="1.55175e-09 -0.01775 -7.75877e-10" rpy="1.5708 -1.5708 0"/>
    </visual>
    <visual>
      <geometry>
        <mesh filename="package://urdf/f3516f363c4dfdeb49895426ad64acab9d85cee8.stl"/>
      </geometry>
      <material name="mx28_elbow_mx28_arm_10_3_material">
        <color rgba="0.5 0.5 0.5 1.0"/>
      </material>
      <origin xyz="-1.81402e-09 0.02075 9.07011e-10" rpy="1.5708 -1.5708 0"/>
    </visual>
    <visual>
      <geometry>
        <mesh filename="package://urdf/f14dd39e029f8996e3026773ee23983bf9c6aaf9.stl"/>
      </geometry>
      <material name="mx28_elbow_tag_10_4_material">
        <color rgba="0.9 0.9 0.9 1.0"/>
      </material>
      <origin xyz="2.64454e-09 -0.01775 -0.025" rpy="-1.5708 4.37114e-08 -3.14159"/>
    </visual>
    <visual>
      <geometry>
        <mesh filename="package://urdf/88369675ab7813e9f9ce85ac3aa8fb33e50350f8.stl"/>
      </geometry>
      <material name="mx28_elbow_mx28_l_10_5_material">
        <color rgba="0.8 0.8 0.8 1.0"/>
      </material>
      <origin xyz="1.67415e-09 1.67415e-09 -0.0383" rpy="-4.37114e-08 -4.37114e-08 1.5708"/>
    </visual>
    <inertial>
      <origin xyz="-0.00359143 -9.63909e-05 -0.0268066" rpy="0 0 0"/>
      <mass value="0.121691"/>
      <inertia ixx="0.000117491"  ixy="4.21275e-08"  ixz="-1.72238e-05" iyy="0.00011693" iyz="2.11919e-08" izz="3.09942e-05" />
    </inertial>
    <collision>
      <origin xyz="-0.002 1.4993e-09 -0.0383" rpy="-4.37114e-08 -4.37114e-08 1.5708"/>
      <geometry>
        <box size="0.0354 0.0374 0.0018"/>
      </geometry>
    </collision>
    <collision>
      <origin xyz="-0.0198 8.48001e-10 -0.059" rpy="-4.37114e-08 -4.37114e-08 1.5708"/>
      <geometry>
        <box size="0.0354 0.0018 0.0412"/>
      </geometry>
    </collision>
    <collision>
      <origin xyz="-0.0108 2.53963e-09 -0.0797" rpy="-1.5708 1.5708 0"/>
      <geometry>
        <cylinder radius="0.0098" length="0.0354"/>
      </geometry>
    </collision>
    <collision>
      <origin xyz="5.46392e-10 5.46392e-10 -0.0125" rpy="-1.5708 4.37114e-08 -3.14159"/>
      <geometry>
        <box size="0.0354 0.0504 0.0353"/>
      </geometry>
    </collision>
  </link>
  <joint name="right_elbow" type="revolute">
    <parent link="right_shoulder_roll"/>
    <child link="right_elbow"/>
    <axis xyz="0 1 0"/>
    <origin xyz="0.0122 3.4838e-09 -0.0797" rpy="0 -5.47945e-24 1.32349e-23"/>
    <limit effort="2.8" velocity="12" lower="-3.14159" upper="3.14159"/>
  </joint>
  <link name="right_arm_tip">
    <inertial>
      <origin xyz="0 0 0" rpy="0 0 0" />
      <mass value="0" />
      <inertia ixx="0" ixy="0" ixz="0" iyy="0" iyz="0" izz="0" />
    </inertial>
  </link>
  <joint name="right_arm_tip" type="fixed">
    <origin xyz="-0.0108 2.53963e-09 -0.0797" rpy="4.37114e-08 -4.37114e-08 8.74228e-08"/>
    <parent link="right_elbow" />
    <child link="right_arm_tip" />
    <axis xyz="0 0 0" />
  </joint>

  <!-- Component mx64_u_arm#11 -->

  <link name="left_hip_yaw">
    <visual>
      <geometry>
        <mesh filename="package://urdf/ec37fb5994935cac6b903c383fe7bf300d33ef4f.stl"/>
      </geometry>
      <material name="mx64_u_arm_mx64_u_arm_11_0_material">
        <color rgba="0.8 0.8 0.8 1.0"/>
      </material>
      <origin xyz="3.67441e-34 3.00039e-18 -0.0245" rpy="-3.14159 -5.35312e-24 4.37114e-08"/>
    </visual>
    <visual>
      <geometry>
        <mesh filename="package://urdf/40e2500861f63fa0d75c3dd3c8fdd0ec8d70ece5.stl"/>
      </geometry>
      <material name="mx64_u_arm_mx64_u_11_1_material">
        <color rgba="0.8 0.8 0.8 1.0"/>
      </material>
      <origin xyz="3.67441e-34 3.00039e-18 -0.0245" rpy="-3.14159 -5.35312e-24 4.37114e-08"/>
    </visual>
    <inertial>
      <origin xyz="-0.000506838 -2.21546e-11 -0.0373359" rpy="0 0 0"/>
      <mass value="0.032317"/>
      <inertia ixx="8.54961e-06"  ixy="-8.88178e-24"  ixz="-2.83665e-09" iyy="2.08698e-05" iyz="-5.68434e-23" izz="1.69968e-05" />
    </inertial>
    <collision>
      <origin xyz="-0.0245 -1.07093e-09 -0.0395" rpy="-3.14159 -5.35312e-24 4.37114e-08"/>
      <geometry>
        <box size="0.0018 0.0298 0.0298"/>
      </geometry>
    </collision>
    <collision>
      <origin xyz="-0.0245 -1.07093e-09 -0.0545" rpy="-3.14159 -1.5708 0"/>
      <geometry>
        <cylinder radius="0.0148" length="0.0018"/>
      </geometry>
    </collision>
    <collision>
      <origin xyz="0.0245 1.07093e-09 -0.0395" rpy="-3.14159 -5.35312e-24 4.37114e-08"/>
      <geometry>
        <box size="0.0018 0.0298 0.0298"/>
      </geometry>
    </collision>
    <collision>
      <origin xyz="0.0245 1.07093e-09 -0.0545" rpy="-3.14159 -1.5708 0"/>
      <geometry>
        <cylinder radius="0.0148" length="0.0018"/>
      </geometry>
    </collision>
    <collision>
      <origin xyz="3.67441e-34 3.00039e-18 -0.0245" rpy="-3.14159 -5.35312e-24 4.37114e-08"/>
      <geometry>
        <box size="0.0508 0.0298 0.0018"/>
      </geometry>
    </collision>
  </link>
  <joint name="left_hip_yaw" type="revolute">
    <parent link="trunk"/>
    <child link="left_hip_yaw"/>
    <axis xyz="0 0 1"/>
    <origin xyz="0 0.046375 0.0205" rpy="0 -0 0"/>
    <limit effort="6.4" velocity="14" lower="-3.14159" upper="3.14159"/>
  </joint>

  <!-- Component mx64_block#12 -->

  <link name="left_hip_roll">
    <visual>
      <geometry>
        <mesh filename="package://urdf/ca50ae7d456653e15dfc15ff54aabe7e237591c9.stl"/>
      </geometry>
      <material name="mx64_block_mx64_block_12_0_material">
        <color rgba="0.8 0.8 0.8 1.0"/>
      </material>
      <origin xyz="-0.047 -2.05444e-09 1.04361e-17" rpy="-3.14159 -1.5708 0"/>
    </visual>
    <visual>
      <geometry>
        <mesh filename="package://urdf/ec48c503b08df80db4b69bdca79c3c4abd9a9f79.stl"/>
      </geometry>
      <material name="mx64_block_mx64_12_1_material">
        <color rgba="0.15 0.2 0.15 1.0"/>
      </material>
      <origin xyz="-0.047 -2.05444e-09 1.04361e-17" rpy="-3.14159 -1.5708 0"/>
    </visual>
    <visual>
      <geometry>
        <mesh filename="package://urdf/25b260d037c322d47acdc54ca73d53b468bfe2d1.stl"/>
      </geometry>
      <material name="mx64_block_mx64_arm_12_2_material">
        <color rgba="0.5 0.5 0.5 1.0"/>
      </material>
      <origin xyz="-0.0265 -1.15835e-09 5.88419e-18" rpy="-3.14159 -1.5708 0"/>
    </visual>
    <visual>
      <geometry>
        <mesh filename="package://urdf/25b260d037c322d47acdc54ca73d53b468bfe2d1.stl"/>
      </geometry>
      <material name="mx64_block_mx64_arm_12_3_material">
        <color rgba="0.5 0.5 0.5 1.0"/>
      </material>
      <origin xyz="-0.0705 -3.08165e-09 1.56542e-17" rpy="-3.14159 -1.5708 0"/>
    </visual>
    <visual>
      <geometry>
        <mesh filename="package://urdf/f14dd39e029f8996e3026773ee23983bf9c6aaf9.stl"/>
      </geometry>
      <material name="mx64_block_tag_12_4_material">
        <color rgba="0.9 0.9 0.9 1.0"/>
      </material>
      <origin xyz="-0.0265 -1.15835e-09 -0.035" rpy="-1.5708 -9.958e-17 -1.5708"/>
    </visual>
    <visual>
      <geometry>
        <mesh filename="package://urdf/ec48c503b08df80db4b69bdca79c3c4abd9a9f79.stl"/>
      </geometry>
      <material name="mx64_block_mx64_12_5_material">
        <color rgba="0.15 0.2 0.15 1.0"/>
      </material>
      <origin xyz="0 0 0" rpy="-1.5708 -1.5708 0"/>
    </visual>
    <visual>
      <geometry>
        <mesh filename="package://urdf/25b260d037c322d47acdc54ca73d53b468bfe2d1.stl"/>
      </geometry>
      <material name="mx64_block_mx64_arm_12_6_material">
        <color rgba="0.5 0.5 0.5 1.0"/>
      </material>
      <origin xyz="-8.96083e-10 0.0205 2.51053e-18" rpy="-1.5708 -1.5708 0"/>
    </visual>
    <visual>
      <geometry>
        <mesh filename="package://urdf/25b260d037c322d47acdc54ca73d53b468bfe2d1.stl"/>
      </geometry>
      <material name="mx64_block_mx64_arm_12_7_material">
        <color rgba="0.5 0.5 0.5 1.0"/>
      </material>
      <origin xyz="1.02722e-09 -0.0235 -2.87793e-18" rpy="-1.5708 -1.5708 0"/>
    </visual>
    <visual>
      <geometry>
        <mesh filename="package://urdf/f14dd39e029f8996e3026773ee23983bf9c6aaf9.stl"/>
      </geometry>
      <material name="mx64_block_tag_12_8_material">
        <color rgba="0.9 0.9 0.9 1.0"/>
      </material>
      <origin xyz="-8.96083e-10 0.0205 -0.035" rpy="-1.5708 -5.35312e-24 4.37114e-08"/>
    </visual>
    <visual>
      <geometry>
        <mesh filename="package://urdf/25b260d037c322d47acdc54ca73d53b468bfe2d1.stl"/>
      </geometry>
      <material name="mx64_block_mx64_arm_12_9_material">
        <color rgba="0.5 0.5 0.5 1.0"/>
      </material>
      <origin xyz="0.0201 8.78599e-10 -4.4631e-18" rpy="-3.14159 -1.5708 0"/>
    </visual>
    <inertial>
      <origin xyz="-0.0225454 -0.000152445 -0.0139042" rpy="0 0 0"/>
      <mass value="0.288805"/>
      <inertia ixx="0.000257701"  ixy="-3.42917e-07"  ixz="-4.10246e-06" iyy="0.000293035" iyz="-9.92596e-07" izz="0.000121563" />
    </inertial>
    <collision>
      <origin xyz="-0.047 -2.05444e-09 -0.018" rpy="-1.5708 -9.958e-17 -1.5708"/>
      <geometry>
        <box size="0.04 0.0609 0.0408"/>
      </geometry>
    </collision>
    <collision>
      <origin xyz="0 2.20437e-18 -0.018" rpy="-1.5708 -5.35312e-24 4.37114e-08"/>
      <geometry>
        <box size="0.04 0.0609 0.0408"/>
      </geometry>
    </collision>
  </link>
  <joint name="left_hip_roll" type="revolute">
    <parent link="left_hip_yaw"/>
    <child link="left_hip_roll"/>
    <axis xyz="1 0 0"/>
    <origin xyz="8.17369e-34 6.67434e-18 -0.0545" rpy="-1.05083e-32 -0 0"/>
    <limit effort="6.4" velocity="14" lower="-3.14159" upper="3.14159"/>
  </joint>

  <!-- Component mx64_u_arm_to_side#13 -->

  <link name="left_hip_pitch">
    <visual>
      <geometry>
        <mesh filename="package://urdf/e2b6cfe73e1fd2427ccfcbdf9c5c458af0d985e7.stl"/>
      </geometry>
      <material name="mx64_u_arm_to_side_mx64_u_arm_to_side_13_0_material">
        <color rgba="0.8 0.8 0.8 1.0"/>
      </material>
      <origin xyz="4.2796e-16 -1.03946e-08 -0.1189" rpy="-2.22045e-16 -8.74228e-08 -1.5708"/>
    </visual>
    <visual>
      <geometry>
        <mesh filename="package://urdf/ec48c503b08df80db4b69bdca79c3c4abd9a9f79.stl"/>
      </geometry>
      <material name="mx64_u_arm_to_side_mx64_13_1_material">
        <color rgba="0.15 0.2 0.15 1.0"/>
      </material>
      <origin xyz="5.03906e-16 -1.22392e-08 -0.14" rpy="1.5708 2.22045e-16 4.37114e-08"/>
    </visual>
    <visual>
      <geometry>
        <mesh filename="package://urdf/25b260d037c322d47acdc54ca73d53b468bfe2d1.stl"/>
      </geometry>
      <material name="mx64_u_arm_to_side_mx64_arm_13_2_material">
        <color rgba="0.5 0.5 0.5 1.0"/>
      </material>
      <origin xyz="8.96084e-10 -0.0205 -0.14" rpy="1.5708 2.22045e-16 4.37114e-08"/>
    </visual>
    <visual>
      <geometry>
        <mesh filename="package://urdf/25b260d037c322d47acdc54ca73d53b468bfe2d1.stl"/>
      </geometry>
      <material name="mx64_u_arm_to_side_mx64_arm_13_3_material">
        <color rgba="0.5 0.5 0.5 1.0"/>
      </material>
      <origin xyz="-1.02722e-09 0.0235 -0.14" rpy="1.5708 2.22045e-16 4.37114e-08"/>
    </visual>
    <visual>
      <geometry>
        <mesh filename="package://urdf/f14dd39e029f8996e3026773ee23983bf9c6aaf9.stl"/>
      </geometry>
      <material name="mx64_u_arm_to_side_tag_13_4_material">
        <color rgba="0.9 0.9 0.9 1.0"/>
      </material>
      <origin xyz="-0.035 -0.0205 -0.14" rpy="1.5708 -1.5708 0"/>
    </visual>
    <visual>
      <geometry>
        <mesh filename="package://urdf/6be08d8e010e5839886db14da5a6263c941ff1bc.stl"/>
      </geometry>
      <material name="mx64_u_arm_to_side_mx64_u_13_5_material">
        <color rgba="0.8 0.8 0.8 1.0"/>
      </material>
      <origin xyz="4.2796e-16 -1.03946e-08 -0.1189" rpy="-2.22045e-16 -8.74228e-08 -1.5708"/>
    </visual>
    <inertial>
      <origin xyz="-0.00917061 0.000379397 -0.113155" rpy="0 0 0"/>
      <mass value="0.218939"/>
      <inertia ixx="0.000492068"  ixy="4.92539e-07"  ixz="7.08778e-07" iyy="0.000504914" iyz="-5.38995e-05" izz="0.000121477" />
    </inertial>
    <collision>
      <origin xyz="-1.07093e-09 0.0245 -0.05945" rpy="-2.22045e-16 -8.74228e-08 -1.5708"/>
      <geometry>
        <box size="0.0018 0.0298 0.1187"/>
      </geometry>
    </collision>
    <collision>
      <origin xyz="-1.07093e-09 0.0245 -2.14186e-09" rpy="1.5708 1.5708 0"/>
      <geometry>
        <cylinder radius="0.0148" length="0.0018"/>
      </geometry>
    </collision>
    <collision>
      <origin xyz="1.07093e-09 -0.0245 -0.05945" rpy="-2.22045e-16 -8.74228e-08 -1.5708"/>
      <geometry>
        <box size="0.0018 0.0298 0.1187"/>
      </geometry>
    </collision>
    <collision>
      <origin xyz="1.07093e-09 -0.0245 2.14186e-09" rpy="1.5708 1.5708 0"/>
      <geometry>
        <cylinder radius="0.0148" length="0.0018"/>
      </geometry>
    </collision>
    <collision>
      <origin xyz="4.2796e-16 -1.03946e-08 -0.1189" rpy="-2.22045e-16 -8.74228e-08 -1.5708"/>
      <geometry>
        <box size="0.0508 0.0298 0.0018"/>
      </geometry>
    </collision>
    <collision>
      <origin xyz="-0.018 -1.3026e-08 -0.14" rpy="1.5708 -1.5708 0"/>
      <geometry>
        <box size="0.04 0.0609 0.0408"/>
      </geometry>
    </collision>
  </link>
  <joint name="left_hip_pitch" type="revolute">
    <parent link="left_hip_roll"/>
    <child link="left_hip_pitch"/>
    <axis xyz="0 1 0"/>
    <origin xyz="0 0 0" rpy="0 -1.85711e-32 0"/>
    <limit effort="6.4" velocity="14" lower="-3.14159" upper="3.14159"/>
  </joint>

  <!-- Component mx64_arms#14 -->

  <link name="left_knee">
    <visual>
      <geometry>
        <mesh filename="package://urdf/5495ce21c8f75def8d90084449f801701d8a1dc9.stl"/>
      </geometry>
      <material name="mx64_arms_mx64_arms_14_0_material">
        <color rgba="0.8 0.8 0.8 1.0"/>
      </material>
      <origin xyz="-3.0598e-09 -6.11959e-09 -0.07" rpy="1.5708 -1.5708 0"/>
    </visual>
    <visual>
      <geometry>
        <mesh filename="package://urdf/c8cae62de47e73927ee995fa8e8e73b00b45320a.stl"/>
      </geometry>
      <material name="mx64_arms_mx64_arms_plate_14_1_material">
        <color rgba="0.8 0.8 0.8 1.0"/>
      </material>
      <origin xyz="-2.03258e-09 -0.0235 -0.07" rpy="1.5708 -1.5708 0"/>
    </visual>
    <visual>
      <geometry>
        <mesh filename="package://urdf/c8cae62de47e73927ee995fa8e8e73b00b45320a.stl"/>
      </geometry>
      <material name="mx64_arms_mx64_arms_plate_14_2_material">
        <color rgba="0.8 0.8 0.8 1.0"/>
      </material>
      <origin xyz="-4.21815e-09 0.0265 -0.07" rpy="1.5708 -1.5708 0"/>
    </visual>
    <inertial>
      <origin xyz="-3.08493e-09 0.000499994 -0.070075" rpy="0 0 0"/>
      <mass value="0.078404"/>
      <inertia ixx="5.40315e-05"  ixy="-9.09495e-22"  ixz="1.06581e-23" iyy="0.000230305" iyz="0" izz="0.000186293" />
    </inertial>
    <collision>
      <origin xyz="-1.98887e-09 -0.0245 -0.07" rpy="1.5708 -1.5708 0"/>
      <geometry>
        <box size="0.1728 0.0278 0.0018"/>
      </geometry>
    </collision>
    <collision>
      <origin xyz="-4.17444e-09 0.0255 -0.07" rpy="1.5708 -1.5708 0"/>
      <geometry>
        <box size="0.1728 0.0278 0.0018"/>
      </geometry>
    </collision>
  </link>
  <joint name="left_knee" type="revolute">
    <parent link="left_hip_pitch"/>
    <child link="left_knee"/>
    <axis xyz="0 1 0"/>
    <origin xyz="5.03906e-16 -1.22392e-08 -0.14" rpy="0 -0 -6.61744e-24"/>
    <limit effort="6.4" velocity="14" lower="-3.14159" upper="3.14159"/>
  </joint>

  <!-- Component mx64_block#15 -->

  <link name="left_ankle_pitch">
    <visual>
      <geometry>
        <mesh filename="package://urdf/ca50ae7d456653e15dfc15ff54aabe7e237591c9.stl"/>
      </geometry>
      <material name="mx64_block_mx64_block_15_0_material">
        <color rgba="0.8 0.8 0.8 1.0"/>
      </material>
      <origin xyz="-0.047 -2.05444e-09 -2.05444e-09" rpy="-4.37114e-08 1.5708 0"/>
    </visual>
    <visual>
      <geometry>
        <mesh filename="package://urdf/ec48c503b08df80db4b69bdca79c3c4abd9a9f79.stl"/>
      </geometry>
      <material name="mx64_block_mx64_15_1_material">
        <color rgba="0.15 0.2 0.15 1.0"/>
      </material>
      <origin xyz="-0.047 -2.05444e-09 -2.05444e-09" rpy="-4.37114e-08 1.5708 0"/>
    </visual>
    <visual>
      <geometry>
        <mesh filename="package://urdf/25b260d037c322d47acdc54ca73d53b468bfe2d1.stl"/>
      </geometry>
      <material name="mx64_block_mx64_arm_15_2_material">
        <color rgba="0.5 0.5 0.5 1.0"/>
      </material>
      <origin xyz="-0.0265 -1.15835e-09 -1.15835e-09" rpy="-4.37114e-08 1.5708 0"/>
    </visual>
    <visual>
      <geometry>
        <mesh filename="package://urdf/25b260d037c322d47acdc54ca73d53b468bfe2d1.stl"/>
      </geometry>
      <material name="mx64_block_mx64_arm_15_3_material">
        <color rgba="0.5 0.5 0.5 1.0"/>
      </material>
      <origin xyz="-0.0705 -3.08165e-09 -3.08165e-09" rpy="-4.37114e-08 1.5708 0"/>
    </visual>
    <visual>
      <geometry>
        <mesh filename="package://urdf/f14dd39e029f8996e3026773ee23983bf9c6aaf9.stl"/>
      </geometry>
      <material name="mx64_block_tag_15_4_material">
        <color rgba="0.9 0.9 0.9 1.0"/>
      </material>
      <origin xyz="-0.0265 1.90145e-09 0.035" rpy="1.5708 8.74228e-08 1.5708"/>
    </visual>
    <visual>
      <geometry>
        <mesh filename="package://urdf/ec48c503b08df80db4b69bdca79c3c4abd9a9f79.stl"/>
      </geometry>
      <material name="mx64_block_mx64_15_5_material">
        <color rgba="0.15 0.2 0.15 1.0"/>
      </material>
      <origin xyz="0 0 0" rpy="1.5708 1.5708 0"/>
    </visual>
    <visual>
      <geometry>
        <mesh filename="package://urdf/25b260d037c322d47acdc54ca73d53b468bfe2d1.stl"/>
      </geometry>
      <material name="mx64_block_mx64_arm_15_6_material">
        <color rgba="0.5 0.5 0.5 1.0"/>
      </material>
      <origin xyz="8.96083e-10 -0.0205 1.79217e-09" rpy="1.5708 1.5708 0"/>
    </visual>
    <visual>
      <geometry>
        <mesh filename="package://urdf/25b260d037c322d47acdc54ca73d53b468bfe2d1.stl"/>
      </geometry>
      <material name="mx64_block_mx64_arm_15_7_material">
        <color rgba="0.5 0.5 0.5 1.0"/>
      </material>
      <origin xyz="-1.02722e-09 0.0235 -2.05444e-09" rpy="1.5708 1.5708 0"/>
    </visual>
    <visual>
      <geometry>
        <mesh filename="package://urdf/f14dd39e029f8996e3026773ee23983bf9c6aaf9.stl"/>
      </geometry>
      <material name="mx64_block_tag_15_8_material">
        <color rgba="0.9 0.9 0.9 1.0"/>
      </material>
      <origin xyz="-6.33815e-10 -0.0205 0.035" rpy="1.5708 -4.37114e-08 4.37114e-08"/>
    </visual>
    <visual>
      <geometry>
        <mesh filename="package://urdf/25b260d037c322d47acdc54ca73d53b468bfe2d1.stl"/>
      </geometry>
      <material name="mx64_block_mx64_arm_15_9_material">
        <color rgba="0.5 0.5 0.5 1.0"/>
      </material>
      <origin xyz="0.0201 8.78599e-10 8.78599e-10" rpy="-4.37114e-08 1.5708 0"/>
    </visual>
    <inertial>
      <origin xyz="-0.0225454 0.000152444 0.0139042" rpy="0 0 0"/>
      <mass value="0.288805"/>
      <inertia ixx="0.000257701"  ixy="-3.42917e-07"  ixz="-4.10246e-06" iyy="0.000293035" iyz="-9.92596e-07" izz="0.000121563" />
    </inertial>
    <collision>
      <origin xyz="-0.047 -4.80825e-10 0.018" rpy="1.5708 8.74228e-08 1.5708"/>
      <geometry>
        <box size="0.04 0.0609 0.0408"/>
      </geometry>
    </collision>
    <collision>
      <origin xyz="-7.86805e-10 1.57361e-09 0.018" rpy="1.5708 -4.37114e-08 4.37114e-08"/>
      <geometry>
        <box size="0.04 0.0609 0.0408"/>
      </geometry>
    </collision>
  </link>
  <joint name="left_ankle_pitch" type="revolute">
    <parent link="left_knee"/>
    <child link="left_ankle_pitch"/>
    <axis xyz="0 1 0"/>
    <origin xyz="-6.11959e-09 -1.22392e-08 -0.14" rpy="0 -7.57953e-26 -6.61744e-24"/>
    <limit effort="6.4" velocity="14" lower="-3.14159" upper="3.14159"/>
  </joint>

  <!-- Component mx64_foot#16 -->

  <link name="left_ankle_roll">
    <visual>
      <geometry>
        <mesh filename="package://urdf/a9ffc03c42a76759d562e38a15ba3176909ccd81.stl"/>
      </geometry>
      <material name="mx64_foot_mx64_foot_16_0_material">
        <color rgba="0.8 0.8 0.8 1.0"/>
      </material>
      <origin xyz="1.31134e-09 -2.62268e-09 -0.03" rpy="-8.74228e-08 -4.37114e-08 4.37114e-08"/>
    </visual>
    <visual>
      <geometry>
        <mesh filename="package://urdf/3e78e2aa8de18b5f0e80d8ac55b396534b0ad6af.stl"/>
      </geometry>
      <material name="mx64_foot_mx64_u_16_1_material">
        <color rgba="0.8 0.8 0.8 1.0"/>
      </material>
      <origin xyz="1.31134e-09 -2.62268e-09 -0.03" rpy="-8.74228e-08 -4.37114e-08 4.37114e-08"/>
    </visual>
    <visual>
      <geometry>
        <mesh filename="package://urdf/5b4db288fcc39ad3a7f74e9372d0e217496d93d2.stl"/>
      </geometry>
      <material name="mx64_foot_foot_16_2_material">
        <color rgba="0.8 0.8 0.8 1.0"/>
      </material>
      <origin xyz="1.18021e-09 0.005 -0.032" rpy="-8.74228e-08 -4.37114e-08 4.37114e-08"/>
    </visual>
    <inertial>
      <origin xyz="-8.32528e-05 0.00416746 -0.0354118" rpy="0 0 0"/>
      <mass value="0.196741"/>
      <inertia ixx="0.000178374"  ixy="-6.82609e-08"  ixz="2.96051e-07" iyy="0.000499794" iyz="2.96051e-06" izz="0.000608649" />
    </inertial>
    <collision>
      <origin xyz="-0.0245 -2.38227e-09 -0.015" rpy="-8.74228e-08 -4.37114e-08 4.37114e-08"/>
      <geometry>
        <box size="0.0018 0.0298 0.0298"/>
      </geometry>
    </collision>
    <collision>
      <origin xyz="-0.0245 -1.07093e-09 -1.07093e-09" rpy="-4.37114e-08 1.5708 0"/>
      <geometry>
        <cylinder radius="0.0148" length="0.0018"/>
      </geometry>
    </collision>
    <collision>
      <origin xyz="0.0245 -2.40413e-10 -0.015" rpy="-8.74228e-08 -4.37114e-08 4.37114e-08"/>
      <geometry>
        <box size="0.0018 0.0298 0.0298"/>
      </geometry>
    </collision>
    <collision>
      <origin xyz="0.0245 1.07093e-09 1.07093e-09" rpy="-4.37114e-08 1.5708 0"/>
      <geometry>
        <cylinder radius="0.0148" length="0.0018"/>
      </geometry>
    </collision>
    <collision>
      <origin xyz="1.31134e-09 -2.62268e-09 -0.03" rpy="-8.74228e-08 -4.37114e-08 4.37114e-08"/>
      <geometry>
        <box size="0.0508 0.0298 0.0018"/>
      </geometry>
    </collision>
    <collision>
      <origin xyz="1.18021e-09 0.005 -0.032" rpy="-8.74228e-08 -4.37114e-08 4.37114e-08"/>
      <geometry>
        <box size="0.1418 0.0818 0.0018"/>
      </geometry>
    </collision>
    <collision>
      <origin xyz="-0.066 -0.031 -0.0395" rpy="-8.74228e-08 -4.37114e-08 4.37114e-08"/>
      <geometry>
        <cylinder radius="0.0048" length="0.0148"/>
      </geometry>
    </collision>
    <collision>
      <origin xyz="-0.066 -0.031 -0.053" rpy="-8.74228e-08 -4.37114e-08 4.37114e-08"/>
      <geometry>
        <sphere radius="0.0088"/>
      </geometry>
    </collision>
    <collision>
      <origin xyz="-0.066 0.041 -0.0395" rpy="-8.74228e-08 -4.37114e-08 4.37114e-08"/>
      <geometry>
        <cylinder radius="0.0048" length="0.0148"/>
      </geometry>
    </collision>
    <collision>
      <origin xyz="-0.066 0.041 -0.053" rpy="-8.74228e-08 -4.37114e-08 4.37114e-08"/>
      <geometry>
        <sphere radius="0.0088"/>
      </geometry>
    </collision>
    <collision>
      <origin xyz="0.066 -0.031 -0.0395" rpy="-8.74228e-08 -4.37114e-08 4.37114e-08"/>
      <geometry>
        <cylinder radius="0.0048" length="0.0148"/>
      </geometry>
    </collision>
    <collision>
      <origin xyz="0.066 -0.031 -0.053" rpy="-8.74228e-08 -4.37114e-08 4.37114e-08"/>
      <geometry>
        <sphere radius="0.0088"/>
      </geometry>
    </collision>
    <collision>
      <origin xyz="0.066 0.041 -0.0395" rpy="-8.74228e-08 -4.37114e-08 4.37114e-08"/>
      <geometry>
        <cylinder radius="0.0048" length="0.0148"/>
      </geometry>
    </collision>
    <collision>
      <origin xyz="0.066 0.041 -0.053" rpy="-8.74228e-08 -4.37114e-08 4.37114e-08"/>
      <geometry>
        <sphere radius="0.0088"/>
      </geometry>
    </collision>
  </link>
  <joint name="left_ankle_roll" type="revolute">
    <parent link="left_ankle_pitch"/>
    <child link="left_ankle_roll"/>
    <axis xyz="1 0 0"/>
    <origin xyz="0 0 0" rpy="1.83244e-25 6.61744e-24 -6.61744e-24"/>
    <limit effort="6.4" velocity="14" lower="-3.14159" upper="3.14159"/>
  </joint>
  <link name="left_foot_tip">
    <inertial>
      <origin xyz="0 0 0" rpy="0 0 0" />
      <mass value="0" />
      <inertia ixx="0" ixy="0" ixz="0" iyy="0" iyz="0" izz="0" />
    </inertial>
  </link>
  <joint name="left_foot_tip" type="fixed">
    <origin xyz="2.66639e-09 -5.33279e-09 -0.061" rpy="-8.74228e-08 -4.37114e-08 4.37114e-08"/>
    <parent link="left_ankle_roll" />
    <child link="left_foot_tip" />
    <axis xyz="0 0 0" />
  </joint>

  <!-- Component mx28_u_arm#17 -->

  <link name="left_shoulder_pitch">
    <visual>
      <geometry>
        <mesh filename="package://urdf/9c1012ad5d1ae82ddba70bad79a3843487f16b4f.stl"/>
      </geometry>
      <material name="mx28_u_arm_mx28_u_arm_17_0_material">
        <color rgba="0.8 0.8 0.8 1.0"/>
      </material>
      <origin xyz="7.49309e-18 0.02175 -4.82948e-18" rpy="1.5708 -2.22045e-16 3.14159"/>
    </visual>
    <visual>
      <geometry>
        <mesh filename="package://urdf/194815b7aa6504c4310c5fff46b0aa33332a958f.stl"/>
      </geometry>
      <material name="mx28_u_arm_mx28_u_17_1_material">
        <color rgba="0.8 0.8 0.8 1.0"/>
      </material>
      <origin xyz="7.49309e-18 0.02175 -4.82948e-18" rpy="1.5708 -2.22045e-16 3.14159"/>
    </visual>
    <inertial>
      <origin xyz="1.13938e-17 0.0330724 -7.34356e-18" rpy="0 0 0"/>
      <mass value="0.029002"/>
      <inertia ixx="6.48424e-06"  ixy="0"  ixz="0" iyy="1.49472e-05" iyz="8.88178e-24" izz="1.26475e-05" />
    </inertial>
    <collision>
      <origin xyz="0.02175 0.03425 -1.24345e-17" rpy="1.5708 -2.22045e-16 3.14159"/>
      <geometry>
        <box size="0.0018 0.0298 0.0248"/>
      </geometry>
    </collision>
    <collision>
      <origin xyz="0.02175 0.04675 -1.52101e-17" rpy="1.5708 -2.22045e-16 -1.5708"/>
      <geometry>
        <cylinder radius="0.0148" length="0.0018"/>
      </geometry>
    </collision>
    <collision>
      <origin xyz="-0.02175 0.03425 -2.77556e-18" rpy="1.5708 -2.22045e-16 3.14159"/>
      <geometry>
        <box size="0.0018 0.0298 0.0248"/>
      </geometry>
    </collision>
    <collision>
      <origin xyz="-0.02175 0.04675 -5.55113e-18" rpy="1.5708 -2.22045e-16 -1.5708"/>
      <geometry>
        <cylinder radius="0.0148" length="0.0018"/>
      </geometry>
    </collision>
    <collision>
      <origin xyz="7.49309e-18 0.02175 -4.82948e-18" rpy="1.5708 -2.22045e-16 3.14159"/>
      <geometry>
        <box size="0.0453 0.0298 0.0018"/>
      </geometry>
    </collision>
  </link>
  <joint name="left_shoulder_pitch" type="revolute">
    <parent link="trunk"/>
    <child link="left_shoulder_pitch"/>
    <axis xyz="0 1 0"/>
    <origin xyz="0 0.046375 0.159" rpy="0 -0 0"/>
    <limit effort="2.8" velocity="12" lower="-3.14159" upper="3.14159"/>
  </joint>

  <!-- Component mx28_u_l#18 -->

  <link name="left_shoulder_roll">
    <visual>
      <geometry>
        <mesh filename="package://urdf/5cd934a01ca249c0e5600e30ff006441d57cb7a3.stl"/>
      </geometry>
      <material name="mx28_u_l_mx28_u_l_18_0_material">
        <color rgba="0.8 0.8 0.8 1.0"/>
      </material>
      <origin xyz="-1.54863e-16 1.67415e-09 -0.0383" rpy="2.22045e-16 -4.37114e-08 1.5708"/>
    </visual>
    <visual>
      <geometry>
        <mesh filename="package://urdf/e9f087865029fcd254bd6913f6f702b6f701e249.stl"/>
      </geometry>
      <material name="mx28_u_l_mx28_18_1_material">
        <color rgba="0.15 0.2 0.15 1.0"/>
      </material>
      <origin xyz="0 0 0" rpy="-3.14159 -1.5708 0"/>
    </visual>
    <visual>
      <geometry>
        <mesh filename="package://urdf/f3516f363c4dfdeb49895426ad64acab9d85cee8.stl"/>
      </geometry>
      <material name="mx28_u_l_mx28_arm_18_2_material">
        <color rgba="0.5 0.5 0.5 1.0"/>
      </material>
      <origin xyz="0.01775 1.55175e-09 -7.10543e-18" rpy="-3.14159 -1.5708 0"/>
    </visual>
    <visual>
      <geometry>
        <mesh filename="package://urdf/f3516f363c4dfdeb49895426ad64acab9d85cee8.stl"/>
      </geometry>
      <material name="mx28_u_l_mx28_arm_18_3_material">
        <color rgba="0.5 0.5 0.5 1.0"/>
      </material>
      <origin xyz="-0.02075 -1.81402e-09 7.10543e-18" rpy="-3.14159 -1.5708 0"/>
    </visual>
    <visual>
      <geometry>
        <mesh filename="package://urdf/f14dd39e029f8996e3026773ee23983bf9c6aaf9.stl"/>
      </geometry>
      <material name="mx28_u_l_tag_18_4_material">
        <color rgba="0.9 0.9 0.9 1.0"/>
      </material>
      <origin xyz="0.01775 2.64454e-09 -0.025" rpy="-1.5708 4.37114e-08 -1.5708"/>
    </visual>
    <visual>
      <geometry>
        <mesh filename="package://urdf/a0a3e3041c2350bb54d06f6cc9aaf2cf28ae6be3.stl"/>
      </geometry>
      <material name="mx28_u_l_mx28_l_18_5_material">
        <color rgba="0.8 0.8 0.8 1.0"/>
      </material>
      <origin xyz="-1.54863e-16 1.67415e-09 -0.0383" rpy="2.22045e-16 -4.37114e-08 1.5708"/>
    </visual>
    <visual>
      <geometry>
        <mesh filename="package://urdf/024ff0622d27b0e34823812b1f294c7b27defa57.stl"/>
      </geometry>
      <material name="mx28_u_l_mx28_u_18_6_material">
        <color rgba="0.8 0.8 0.8 1.0"/>
      </material>
      <origin xyz="-0.0178 1.92767e-09 -0.0797" rpy="1.5708 -4.37114e-08 1.5708"/>
    </visual>
    <inertial>
      <origin xyz="-0.00345419 1.20538e-09 -0.0344843" rpy="0 0 0"/>
      <mass value="0.141734"/>
      <inertia ixx="0.00017908"  ixy="1.77636e-24"  ixz="1.06901e-20" iyy="0.000177275" iyz="1.74732e-05" izz="4.7689e-05" />
    </inertial>
    <collision>
      <origin xyz="-0.002 1.4993e-09 -0.0383" rpy="2.22045e-16 -4.37114e-08 1.5708"/>
      <geometry>
        <box size="0.0354 0.0374 0.0018"/>
      </geometry>
    </collision>
    <collision>
      <origin xyz="-0.0198 1.17584e-09 -0.0665" rpy="2.22045e-16 -4.37114e-08 1.5708"/>
      <geometry>
        <box size="0.0354 0.0018 0.0562"/>
      </geometry>
    </collision>
    <collision>
      <origin xyz="-0.0028 -0.02175 -0.0797" rpy="1.5708 -4.37114e-08 1.5708"/>
      <geometry>
        <box size="0.0018 0.0298 0.0298"/>
      </geometry>
    </collision>
    <collision>
      <origin xyz="0.0122 -0.02175 -0.0797" rpy="1.5708 -1.94118e-23 -3.14159"/>
      <geometry>
        <cylinder radius="0.0148" length="0.0018"/>
      </geometry>
    </collision>
    <collision>
      <origin xyz="-0.0028 0.02175 -0.0797" rpy="1.5708 -4.37114e-08 1.5708"/>
      <geometry>
        <box size="0.0018 0.0298 0.0298"/>
      </geometry>
    </collision>
    <collision>
      <origin xyz="0.0122 0.02175 -0.0797" rpy="1.5708 -1.94118e-23 -3.14159"/>
      <geometry>
        <cylinder radius="0.0148" length="0.0018"/>
      </geometry>
    </collision>
    <collision>
      <origin xyz="-0.0178 1.92767e-09 -0.0797" rpy="1.5708 -4.37114e-08 1.5708"/>
      <geometry>
        <box size="0.0453 0.0298 0.0018"/>
      </geometry>
    </collision>
    <collision>
      <origin xyz="-5.05427e-17 5.46392e-10 -0.0125" rpy="-1.5708 4.37114e-08 -1.5708"/>
      <geometry>
        <box size="0.0354 0.0504 0.0353"/>
      </geometry>
    </collision>
  </link>
  <joint name="left_shoulder_roll" type="revolute">
    <parent link="left_shoulder_pitch"/>
    <child link="left_shoulder_roll"/>
    <axis xyz="1 0 0"/>
    <origin xyz="1.61058e-17 0.04675 -1.03806e-17" rpy="4.40543e-25 -3.9443e-31 1.32349e-23"/>
    <limit effort="2.8" velocity="12" lower="-3.14159" upper="3.14159"/>
  </joint>

  <!-- Component mx28_elbow#19 -->

  <link name="left_elbow">
    <visual>
      <geometry>
        <mesh filename="package://urdf/329dbba1976866b0cd7b0f2bdf9a6c14725749b6.stl"/>
      </geometry>
      <material name="mx28_elbow_mx28_elbow_19_0_material">
        <color rgba="0.8 0.8 0.8 1.0"/>
      </material>
      <origin xyz="1.67415e-09 1.67415e-09 -0.0383" rpy="4.37114e-08 -4.37114e-08 1.74846e-07"/>
    </visual>
    <visual>
      <geometry>
        <mesh filename="package://urdf/e9f087865029fcd254bd6913f6f702b6f701e249.stl"/>
      </geometry>
      <material name="mx28_elbow_mx28_19_1_material">
        <color rgba="0.15 0.2 0.15 1.0"/>
      </material>
      <origin xyz="0 0 0" rpy="1.5708 -1.5708 0"/>
    </visual>
    <visual>
      <geometry>
        <mesh filename="package://urdf/f3516f363c4dfdeb49895426ad64acab9d85cee8.stl"/>
      </geometry>
      <material name="mx28_elbow_mx28_arm_19_2_material">
        <color rgba="0.5 0.5 0.5 1.0"/>
      </material>
      <origin xyz="3.10351e-09 -0.01775 -7.75877e-10" rpy="1.5708 -1.5708 0"/>
    </visual>
    <visual>
      <geometry>
        <mesh filename="package://urdf/f3516f363c4dfdeb49895426ad64acab9d85cee8.stl"/>
      </geometry>
      <material name="mx28_elbow_mx28_arm_19_3_material">
        <color rgba="0.5 0.5 0.5 1.0"/>
      </material>
      <origin xyz="-3.62805e-09 0.02075 9.07011e-10" rpy="1.5708 -1.5708 0"/>
    </visual>
    <visual>
      <geometry>
        <mesh filename="package://urdf/f14dd39e029f8996e3026773ee23983bf9c6aaf9.stl"/>
      </geometry>
      <material name="mx28_elbow_tag_19_4_material">
        <color rgba="0.9 0.9 0.9 1.0"/>
      </material>
      <origin xyz="4.19629e-09 -0.01775 -0.025" rpy="-1.5708 4.37114e-08 -3.14159"/>
    </visual>
    <visual>
      <geometry>
        <mesh filename="package://urdf/88369675ab7813e9f9ce85ac3aa8fb33e50350f8.stl"/>
      </geometry>
      <material name="mx28_elbow_mx28_l_19_5_material">
        <color rgba="0.8 0.8 0.8 1.0"/>
      </material>
      <origin xyz="1.67415e-09 1.67415e-09 -0.0383" rpy="-4.37114e-08 -4.37114e-08 1.5708"/>
    </visual>
    <inertial>
      <origin xyz="-0.00359143 -9.63912e-05 -0.0268066" rpy="0 0 0"/>
      <mass value="0.121691"/>
      <inertia ixx="0.000117491"  ixy="4.21275e-08"  ixz="-1.72238e-05" iyy="0.00011693" iyz="2.11919e-08" izz="3.09942e-05" />
    </inertial>
    <collision>
      <origin xyz="-0.002 1.32446e-09 -0.0383" rpy="-4.37114e-08 -4.37114e-08 1.5708"/>
      <geometry>
        <box size="0.0354 0.0374 0.0018"/>
      </geometry>
    </collision>
    <collision>
      <origin xyz="-0.0198 -8.82969e-10 -0.059" rpy="-4.37114e-08 -4.37114e-08 1.5708"/>
      <geometry>
        <box size="0.0354 0.0018 0.0412"/>
      </geometry>
    </collision>
    <collision>
      <origin xyz="-0.0108 1.59547e-09 -0.0797" rpy="-1.5708 1.5708 0"/>
      <geometry>
        <cylinder radius="0.0098" length="0.0354"/>
      </geometry>
    </collision>
    <collision>
      <origin xyz="5.46392e-10 5.46392e-10 -0.0125" rpy="-1.5708 4.37114e-08 -3.14159"/>
      <geometry>
        <box size="0.0354 0.0504 0.0353"/>
      </geometry>
    </collision>
  </link>
  <joint name="left_elbow" type="revolute">
    <parent link="left_shoulder_roll"/>
    <child link="left_elbow"/>
    <axis xyz="0 1 0"/>
    <origin xyz="0.0122 4.55036e-09 -0.0797" rpy="0 -1.75549e-24 0"/>
    <limit effort="2.8" velocity="12" lower="-3.14159" upper="3.14159"/>
  </joint>
  <link name="left_arm_tip">
    <inertial>
      <origin xyz="0 0 0" rpy="0 0 0" />
      <mass value="0" />
      <inertia ixx="0" ixy="0" ixz="0" iyy="0" iyz="0" izz="0" />
    </inertial>
  </link>
  <joint name="left_arm_tip" type="fixed">
    <origin xyz="-0.0108 1.59547e-09 -0.0797" rpy="4.37114e-08 -4.37114e-08 1.74846e-07"/>
    <parent link="left_elbow" />
    <child link="left_arm_tip" />
    <axis xyz="0 0 0" />
  </joint>

  <!-- Component mx28_u_arm#20 -->

  <link name="head_yaw">
    <visual>
      <geometry>
        <mesh filename="package://urdf/6b923c5c4f6b3d3e8c161e3b6897c1aa18a3a292.stl"/>
      </geometry>
      <material name="mx28_u_arm_mx28_u_arm_20_0_material">
        <color rgba="0.8 0.8 0.8 1.0"/>
      </material>
      <origin xyz="0 0 0.02175" rpy="0 -0 -1.5708"/>
    </visual>
    <visual>
      <geometry>
        <mesh filename="package://urdf/86c411ad966dc4d9045f9be113747b7417addb9d.stl"/>
      </geometry>
      <material name="mx28_u_arm_mx28_u_20_1_material">
        <color rgba="0.8 0.8 0.8 1.0"/>
      </material>
      <origin xyz="0 0 0.02175" rpy="0 -0 -1.5708"/>
    </visual>
    <inertial>
      <origin xyz="0 0 0.0352204" rpy="0 0 0"/>
      <mass value="0.031552"/>
      <inertia ixx="8.42675e-06"  ixy="0"  ixz="0" iyy="1.79335e-05" iyz="2.84217e-23" izz="1.40733e-05" />
    </inertial>
    <collision>
      <origin xyz="-4.82948e-18 0.02175 0.03675" rpy="0 -0 -1.5708"/>
      <geometry>
        <box size="0.0018 0.0298 0.0298"/>
      </geometry>
    </collision>
    <collision>
      <origin xyz="-4.82948e-18 0.02175 0.05175" rpy="1.5708 1.5708 0"/>
      <geometry>
        <cylinder radius="0.0148" length="0.0018"/>
      </geometry>
    </collision>
    <collision>
      <origin xyz="4.82948e-18 -0.02175 0.03675" rpy="0 -0 -1.5708"/>
      <geometry>
        <box size="0.0018 0.0298 0.0298"/>
      </geometry>
    </collision>
    <collision>
      <origin xyz="4.82948e-18 -0.02175 0.05175" rpy="1.5708 1.5708 0"/>
      <geometry>
        <cylinder radius="0.0148" length="0.0018"/>
      </geometry>
    </collision>
    <collision>
      <origin xyz="0 0 0.02175" rpy="0 -0 -1.5708"/>
      <geometry>
        <box size="0.0453 0.0298 0.0018"/>
      </geometry>
    </collision>
  </link>
  <joint name="head_yaw" type="revolute">
    <parent link="trunk"/>
    <child link="head_yaw"/>
    <axis xyz="0 0 1"/>
    <origin xyz="0.025873 0 0.16193" rpy="0 -0 0"/>
    <limit effort="2.8" velocity="12" lower="-3.14159" upper="3.14159"/>
  </joint>

  <!-- Component mx28_head#21 -->

  <link name="head_pitch">
    <visual>
      <geometry>
        <mesh filename="package://urdf/ac5b3fd3a7e1b612e3a2bffb9086620de61585c3.stl"/>
      </geometry>
      <material name="mx28_head_mx28_head_21_0_material">
        <color rgba="0.8 0.8 0.8 1.0"/>
      </material>
      <origin xyz="0 0 0" rpy="1.5708 1.5708 0"/>
    </visual>
    <visual>
      <geometry>
        <mesh filename="package://urdf/e9f087865029fcd254bd6913f6f702b6f701e249.stl"/>
      </geometry>
      <material name="mx28_head_mx28_21_1_material">
        <color rgba="0.15 0.2 0.15 1.0"/>
      </material>
      <origin xyz="0 0 0" rpy="1.5708 1.5708 0"/>
    </visual>
    <visual>
      <geometry>
        <mesh filename="package://urdf/f3516f363c4dfdeb49895426ad64acab9d85cee8.stl"/>
      </geometry>
      <material name="mx28_head_mx28_arm_21_2_material">
        <color rgba="0.5 0.5 0.5 1.0"/>
      </material>
      <origin xyz="3.9413e-18 -0.01775 3.9413e-18" rpy="1.5708 1.5708 0"/>
    </visual>
    <visual>
      <geometry>
        <mesh filename="package://urdf/f3516f363c4dfdeb49895426ad64acab9d85cee8.stl"/>
      </geometry>
      <material name="mx28_head_mx28_arm_21_3_material">
        <color rgba="0.5 0.5 0.5 1.0"/>
      </material>
      <origin xyz="-4.60743e-18 0.02075 -4.60743e-18" rpy="1.5708 1.5708 0"/>
    </visual>
    <visual>
      <geometry>
        <mesh filename="package://urdf/f14dd39e029f8996e3026773ee23983bf9c6aaf9.stl"/>
      </geometry>
      <material name="mx28_head_tag_21_4_material">
        <color rgba="0.9 0.9 0.9 1.0"/>
      </material>
      <origin xyz="3.9413e-18 -0.01775 0.025" rpy="1.5708 2.22045e-16 2.22045e-16"/>
    </visual>
    <inertial>
      <origin xyz="3.1977e-20 -0.000144011 0.00959621" rpy="0 0 0"/>
      <mass value="0.081452"/>
      <inertia ixx="1.95072e-05"  ixy="-2.52243e-22"  ixz="1.80686e-07" iyy="2.59718e-05" iyz="3.64153e-23" izz="2.26105e-05" />
    </inertial>
    <collision>
      <origin xyz="2.77556e-18 2.77556e-18 0.0125" rpy="1.5708 2.22045e-16 2.22045e-16"/>
      <geometry>
        <box size="0.0354 0.0504 0.0353"/>
      </geometry>
    </collision>
  </link>
  <joint name="head_pitch" type="revolute">
    <parent link="head_yaw"/>
    <child link="head_pitch"/>
    <axis xyz="0 1 0"/>
    <origin xyz="0 0 0.05175" rpy="0 -0 0"/>
    <limit effort="2.8" velocity="12" lower="-3.14159" upper="3.14159"/>
  </joint>
  <link name="camera">
    <inertial>
      <origin xyz="0 0 0" rpy="0 0 0" />
      <mass value="0" />
      <inertia ixx="0" ixy="0" ixz="0" iyy="0" iyz="0" izz="0" />
    </inertial>
  </link>
  <joint name="camera" type="fixed">
    <origin xyz="0.01 1.53988e-17 0.05935" rpy="0 -0 0"/>
    <parent link="head_pitch" />
    <child link="camera" />
    <axis xyz="0 0 0" />
  </joint>
</robot>
